{"timestamp":"2026-04-25T05:45:11.607632Z","level":"info","event":"DAG bundles loaded: dags-folder","logger":"airflow.dag_processing.bundles.manager.DagBundlesManager","filename":"manager.py","lineno":179}
{"timestamp":"2026-04-25T05:45:11.609017Z","level":"info","event":"Filling up the DagBag from /opt/airflow/dags/hive_msck.py","logger":"airflow.models.dagbag.DagBag","filename":"dagbag.py","lineno":593}
{"timestamp":"2026-04-25T05:45:11.730634Z","level":"warning","event":"The `airflow.decorators.dag` attribute is deprecated. Please use `'airflow.sdk.dag'`.","category":"DeprecatedImportWarning","filename":"/opt/airflow/dags/hive_msck.py","lineno":3,"logger":"py.warnings"}
{"timestamp":"2026-04-25T05:45:11.731108Z","level":"warning","event":"The `airflow.decorators.task` attribute is deprecated. Please use `'airflow.sdk.task'`.","category":"DeprecatedImportWarning","filename":"/opt/airflow/dags/hive_msck.py","lineno":3,"logger":"py.warnings"}
{"timestamp":"2026-04-25T05:45:11.816115Z","level":"info","event":"ssh_hook is not provided or invalid. Trying ssh_conn_id to create SSHHook.","logger":"airflow.task.operators.airflow.providers.ssh.operators.ssh.SSHOperator","filename":"ssh.py","lineno":127}
{"timestamp":"2026-04-25T05:45:11.838023Z","level":"warning","event":"No Host Key Verification. This won't protect against Man-In-The-Middle attacks","logger":"airflow.task.hooks.airflow.providers.ssh.hooks.ssh.SSHHook","filename":"ssh.py","lineno":298}
{"timestamp":"2026-04-25T05:45:11.863059Z","level":"info","event":"Connected (version 2.0, client OpenSSH_8.9p1)","logger":"paramiko.transport","filename":"transport.py","lineno":1944}
{"timestamp":"2026-04-25T05:45:11.949836Z","level":"info","event":"Authentication (password) successful!","logger":"paramiko.transport","filename":"transport.py","lineno":1944}
{"timestamp":"2026-04-25T05:45:11.950632Z","level":"info","event":"Running command: \n        bash -lc '\n        PYTHONPATH=/work/jsy/Unified_Log_Analytics_Platform         spark-submit             --master yarn             --deploy-mode client             --jars /application/apache-hive-3.1.3-bin/lib/hive-hcatalog-core-3.1.3.jar             --num-executors 2             --executor-memory 2G             --executor-cores 1             /application/airflow/script/spark_validation.py             --tables \"auth\"             --dt \"20260424\"\n        '\n        ","logger":"airflow.task.hooks.airflow.providers.ssh.hooks.ssh.SSHHook","filename":"ssh.py","lineno":449}
{"timestamp":"2026-04-25T05:45:17.006930Z","level":"warning","event":"26/04/25 14:45:16 WARN NativeCodeLoader: Unable to load native-hadoop library for your platform... using builtin-java classes where applicable","logger":"airflow.task.hooks.airflow.providers.ssh.hooks.ssh.SSHHook","filename":"ssh.py","lineno":500}
{"timestamp":"2026-04-25T05:45:18.323579Z","level":"info","event":"{'pg_host': '192.168.122.59', 'pg_port': 5432, 'pg_db': 'job_pro', 'pg_user': 'sjj', 'pg_password': '1234'}","logger":"airflow.task.hooks.airflow.providers.ssh.hooks.ssh.SSHHook","filename":"ssh.py","lineno":495}
{"timestamp":"2026-04-25T05:45:18.344553Z","level":"info","event":"PostgreSQL 연결 완료","logger":"airflow.task.hooks.airflow.providers.ssh.hooks.ssh.SSHHook","filename":"ssh.py","lineno":495}
{"timestamp":"2026-04-25T05:45:18.520165Z","level":"warning","event":"26/04/25 14:45:18 INFO SparkContext: Running Spark version 3.4.3","logger":"airflow.task.hooks.airflow.providers.ssh.hooks.ssh.SSHHook","filename":"ssh.py","lineno":500}
{"timestamp":"2026-04-25T05:45:18.636892Z","level":"warning","event":"26/04/25 14:45:18 INFO ResourceUtils: ==============================================================","logger":"airflow.task.hooks.airflow.providers.ssh.hooks.ssh.SSHHook","filename":"ssh.py","lineno":500}
{"timestamp":"2026-04-25T05:45:18.637106Z","level":"warning","event":"26/04/25 14:45:18 INFO ResourceUtils: No custom resources configured for spark.driver.","logger":"airflow.task.hooks.airflow.providers.ssh.hooks.ssh.SSHHook","filename":"ssh.py","lineno":500}
{"timestamp":"2026-04-25T05:45:18.637184Z","level":"warning","event":"26/04/25 14:45:18 INFO ResourceUtils: ==============================================================","logger":"airflow.task.hooks.airflow.providers.ssh.hooks.ssh.SSHHook","filename":"ssh.py","lineno":500}
{"timestamp":"2026-04-25T05:45:18.637247Z","level":"warning","event":"26/04/25 14:45:18 INFO SparkContext: Submitted application: hive_validation","logger":"airflow.task.hooks.airflow.providers.ssh.hooks.ssh.SSHHook","filename":"ssh.py","lineno":500}
{"timestamp":"2026-04-25T05:45:18.715216Z","level":"warning","event":"26/04/25 14:45:18 INFO ResourceProfile: Default ResourceProfile created, executor resources: Map(cores -> name: cores, amount: 1, script: , vendor: , memory -> name: memory, amount: 2048, script: , vendor: , offHeap -> name: offHeap, amount: 0, script: , vendor: ), task resources: Map(cpus -> name: cpus, amount: 1.0)","logger":"airflow.task.hooks.airflow.providers.ssh.hooks.ssh.SSHHook","filename":"ssh.py","lineno":500}
{"timestamp":"2026-04-25T05:45:18.762283Z","level":"warning","event":"26/04/25 14:45:18 INFO ResourceProfile: Limiting resource is cpus at 1 tasks per executor","logger":"airflow.task.hooks.airflow.providers.ssh.hooks.ssh.SSHHook","filename":"ssh.py","lineno":500}
{"timestamp":"2026-04-25T05:45:18.765709Z","level":"warning","event":"26/04/25 14:45:18 INFO ResourceProfileManager: Added ResourceProfile id: 0","logger":"airflow.task.hooks.airflow.providers.ssh.hooks.ssh.SSHHook","filename":"ssh.py","lineno":500}
{"timestamp":"2026-04-25T05:45:18.864133Z","level":"warning","event":"26/04/25 14:45:18 INFO SecurityManager: Changing view acls to: root","logger":"airflow.task.hooks.airflow.providers.ssh.hooks.ssh.SSHHook","filename":"ssh.py","lineno":500}
{"timestamp":"2026-04-25T05:45:18.865007Z","level":"warning","event":"26/04/25 14:45:18 INFO SecurityManager: Changing modify acls to: root","logger":"airflow.task.hooks.airflow.providers.ssh.hooks.ssh.SSHHook","filename":"ssh.py","lineno":500}
{"timestamp":"2026-04-25T05:45:18.865304Z","level":"warning","event":"26/04/25 14:45:18 INFO SecurityManager: Changing view acls groups to: ","logger":"airflow.task.hooks.airflow.providers.ssh.hooks.ssh.SSHHook","filename":"ssh.py","lineno":500}
{"timestamp":"2026-04-25T05:45:18.865999Z","level":"warning","event":"26/04/25 14:45:18 INFO SecurityManager: Changing modify acls groups to: ","logger":"airflow.task.hooks.airflow.providers.ssh.hooks.ssh.SSHHook","filename":"ssh.py","lineno":500}
{"timestamp":"2026-04-25T05:45:18.866626Z","level":"warning","event":"26/04/25 14:45:18 INFO SecurityManager: SecurityManager: authentication disabled; ui acls disabled; users with view permissions: root; groups with view permissions: EMPTY; users with modify permissions: root; groups with modify permissions: EMPTY","logger":"airflow.task.hooks.airflow.providers.ssh.hooks.ssh.SSHHook","filename":"ssh.py","lineno":500}
{"timestamp":"2026-04-25T05:45:19.449281Z","level":"warning","event":"26/04/25 14:45:19 INFO Utils: Successfully started service 'sparkDriver' on port 40015.","logger":"airflow.task.hooks.airflow.providers.ssh.hooks.ssh.SSHHook","filename":"ssh.py","lineno":500}
{"timestamp":"2026-04-25T05:45:19.537822Z","level":"warning","event":"26/04/25 14:45:19 INFO SparkEnv: Registering MapOutputTracker","logger":"airflow.task.hooks.airflow.providers.ssh.hooks.ssh.SSHHook","filename":"ssh.py","lineno":500}
{"timestamp":"2026-04-25T05:45:19.582468Z","level":"warning","event":"26/04/25 14:45:19 INFO SparkEnv: Registering BlockManagerMaster","logger":"airflow.task.hooks.airflow.providers.ssh.hooks.ssh.SSHHook","filename":"ssh.py","lineno":500}
{"timestamp":"2026-04-25T05:45:19.619644Z","level":"warning","event":"26/04/25 14:45:19 INFO BlockManagerMasterEndpoint: Using org.apache.spark.storage.DefaultTopologyMapper for getting topology information","logger":"airflow.task.hooks.airflow.providers.ssh.hooks.ssh.SSHHook","filename":"ssh.py","lineno":500}
{"timestamp":"2026-04-25T05:45:19.620538Z","level":"warning","event":"26/04/25 14:45:19 INFO BlockManagerMasterEndpoint: BlockManagerMasterEndpoint up","logger":"airflow.task.hooks.airflow.providers.ssh.hooks.ssh.SSHHook","filename":"ssh.py","lineno":500}
{"timestamp":"2026-04-25T05:45:19.671500Z","level":"warning","event":"26/04/25 14:45:19 INFO SparkEnv: Registering BlockManagerMasterHeartbeat","logger":"airflow.task.hooks.airflow.providers.ssh.hooks.ssh.SSHHook","filename":"ssh.py","lineno":500}
{"timestamp":"2026-04-25T05:45:19.707853Z","level":"warning","event":"26/04/25 14:45:19 INFO DiskBlockManager: Created local directory at /tmp/blockmgr-5f0674ab-2d09-4691-b4b4-1fcd186d2fdc","logger":"airflow.task.hooks.airflow.providers.ssh.hooks.ssh.SSHHook","filename":"ssh.py","lineno":500}
{"timestamp":"2026-04-25T05:45:19.743586Z","level":"warning","event":"26/04/25 14:45:19 INFO MemoryStore: MemoryStore started with capacity 2.2 GiB","logger":"airflow.task.hooks.airflow.providers.ssh.hooks.ssh.SSHHook","filename":"ssh.py","lineno":500}
{"timestamp":"2026-04-25T05:45:19.806901Z","level":"warning","event":"26/04/25 14:45:19 INFO SparkEnv: Registering OutputCommitCoordinator","logger":"airflow.task.hooks.airflow.providers.ssh.hooks.ssh.SSHHook","filename":"ssh.py","lineno":500}
{"timestamp":"2026-04-25T05:45:20.053666Z","level":"warning","event":"26/04/25 14:45:20 INFO JettyUtils: Start Jetty 0.0.0.0:4040 for SparkUI","logger":"airflow.task.hooks.airflow.providers.ssh.hooks.ssh.SSHHook","filename":"ssh.py","lineno":500}
{"timestamp":"2026-04-25T05:45:20.147431Z","level":"warning","event":"26/04/25 14:45:20 WARN Utils: Service 'SparkUI' could not bind on port 4040. Attempting port 4041.","logger":"airflow.task.hooks.airflow.providers.ssh.hooks.ssh.SSHHook","filename":"ssh.py","lineno":500}
{"timestamp":"2026-04-25T05:45:20.161050Z","level":"warning","event":"26/04/25 14:45:20 INFO Utils: Successfully started service 'SparkUI' on port 4041.","logger":"airflow.task.hooks.airflow.providers.ssh.hooks.ssh.SSHHook","filename":"ssh.py","lineno":500}
{"timestamp":"2026-04-25T05:45:20.763234Z","level":"warning","event":"26/04/25 14:45:20 INFO ConfiguredRMFailoverProxyProvider: Failing over to rm2","logger":"airflow.task.hooks.airflow.providers.ssh.hooks.ssh.SSHHook","filename":"ssh.py","lineno":500}
{"timestamp":"2026-04-25T05:45:21.380733Z","level":"warning","event":"26/04/25 14:45:21 INFO Configuration: resource-types.xml not found","logger":"airflow.task.hooks.airflow.providers.ssh.hooks.ssh.SSHHook","filename":"ssh.py","lineno":500}
{"timestamp":"2026-04-25T05:45:21.381353Z","level":"warning","event":"26/04/25 14:45:21 INFO ResourceUtils: Unable to find 'resource-types.xml'.","logger":"airflow.task.hooks.airflow.providers.ssh.hooks.ssh.SSHHook","filename":"ssh.py","lineno":500}
{"timestamp":"2026-04-25T05:45:21.397841Z","level":"warning","event":"26/04/25 14:45:21 INFO Client: Verifying our application has not requested more than the maximum memory capability of the cluster (5120 MB per container)","logger":"airflow.task.hooks.airflow.providers.ssh.hooks.ssh.SSHHook","filename":"ssh.py","lineno":500}
{"timestamp":"2026-04-25T05:45:21.399636Z","level":"warning","event":"26/04/25 14:45:21 INFO Client: Will allocate AM container, with 896 MB memory including 384 MB overhead","logger":"airflow.task.hooks.airflow.providers.ssh.hooks.ssh.SSHHook","filename":"ssh.py","lineno":500}
{"timestamp":"2026-04-25T05:45:21.400558Z","level":"warning","event":"26/04/25 14:45:21 INFO Client: Setting up container launch context for our AM","logger":"airflow.task.hooks.airflow.providers.ssh.hooks.ssh.SSHHook","filename":"ssh.py","lineno":500}
{"timestamp":"2026-04-25T05:45:21.403590Z","level":"warning","event":"26/04/25 14:45:21 INFO Client: Setting up the launch environment for our AM container","logger":"airflow.task.hooks.airflow.providers.ssh.hooks.ssh.SSHHook","filename":"ssh.py","lineno":500}
{"timestamp":"2026-04-25T05:45:21.412105Z","level":"warning","event":"26/04/25 14:45:21 INFO Client: Preparing resources for our AM container","logger":"airflow.task.hooks.airflow.providers.ssh.hooks.ssh.SSHHook","filename":"ssh.py","lineno":500}
{"timestamp":"2026-04-25T05:45:21.493380Z","level":"warning","event":"26/04/25 14:45:21 WARN Client: Neither spark.yarn.jars nor spark.yarn.archive is set, falling back to uploading libraries under SPARK_HOME.","logger":"airflow.task.hooks.airflow.providers.ssh.hooks.ssh.SSHHook","filename":"ssh.py","lineno":500}
{"timestamp":"2026-04-25T05:45:25.820252Z","level":"warning","event":"26/04/25 14:45:25 INFO Client: Uploading resource file:/tmp/spark-a3cd87ea-1541-4e56-a78e-3af6f13d4442/__spark_libs__247257855710758197.zip -> hdfs://job-cluster/user/root/.sparkStaging/application_1773931628321_0087/__spark_libs__247257855710758197.zip","logger":"airflow.task.hooks.airflow.providers.ssh.hooks.ssh.SSHHook","filename":"ssh.py","lineno":500}
{"timestamp":"2026-04-25T05:45:28.929709Z","level":"warning","event":"26/04/25 14:45:28 INFO Client: Uploading resource file:/application/apache-hive-3.1.3-bin/lib/hive-hcatalog-core-3.1.3.jar -> hdfs://job-cluster/user/root/.sparkStaging/application_1773931628321_0087/hive-hcatalog-core-3.1.3.jar","logger":"airflow.task.hooks.airflow.providers.ssh.hooks.ssh.SSHHook","filename":"ssh.py","lineno":500}
{"timestamp":"2026-04-25T05:45:29.033271Z","level":"warning","event":"26/04/25 14:45:29 INFO Client: Uploading resource file:/application/spark-3.4.3-bin-hadoop3/python/lib/pyspark.zip -> hdfs://job-cluster/user/root/.sparkStaging/application_1773931628321_0087/pyspark.zip","logger":"airflow.task.hooks.airflow.providers.ssh.hooks.ssh.SSHHook","filename":"ssh.py","lineno":500}
{"timestamp":"2026-04-25T05:45:29.149581Z","level":"warning","event":"26/04/25 14:45:29 INFO Client: Uploading resource file:/application/spark-3.4.3-bin-hadoop3/python/lib/py4j-0.10.9.7-src.zip -> hdfs://job-cluster/user/root/.sparkStaging/application_1773931628321_0087/py4j-0.10.9.7-src.zip","logger":"airflow.task.hooks.airflow.providers.ssh.hooks.ssh.SSHHook","filename":"ssh.py","lineno":500}
{"timestamp":"2026-04-25T05:45:29.694187Z","level":"warning","event":"26/04/25 14:45:29 INFO Client: Uploading resource file:/tmp/spark-a3cd87ea-1541-4e56-a78e-3af6f13d4442/__spark_conf__16433162775028727115.zip -> hdfs://job-cluster/user/root/.sparkStaging/application_1773931628321_0087/__spark_conf__.zip","logger":"airflow.task.hooks.airflow.providers.ssh.hooks.ssh.SSHHook","filename":"ssh.py","lineno":500}
{"timestamp":"2026-04-25T05:45:29.767451Z","level":"warning","event":"26/04/25 14:45:29 INFO SecurityManager: Changing view acls to: root","logger":"airflow.task.hooks.airflow.providers.ssh.hooks.ssh.SSHHook","filename":"ssh.py","lineno":500}
{"timestamp":"2026-04-25T05:45:29.767894Z","level":"warning","event":"26/04/25 14:45:29 INFO SecurityManager: Changing modify acls to: root","logger":"airflow.task.hooks.airflow.providers.ssh.hooks.ssh.SSHHook","filename":"ssh.py","lineno":500}
{"timestamp":"2026-04-25T05:45:29.768433Z","level":"warning","event":"26/04/25 14:45:29 INFO SecurityManager: Changing view acls groups to: ","logger":"airflow.task.hooks.airflow.providers.ssh.hooks.ssh.SSHHook","filename":"ssh.py","lineno":500}
{"timestamp":"2026-04-25T05:45:29.768815Z","level":"warning","event":"26/04/25 14:45:29 INFO SecurityManager: Changing modify acls groups to: ","logger":"airflow.task.hooks.airflow.providers.ssh.hooks.ssh.SSHHook","filename":"ssh.py","lineno":500}
{"timestamp":"2026-04-25T05:45:29.769221Z","level":"warning","event":"26/04/25 14:45:29 INFO SecurityManager: SecurityManager: authentication disabled; ui acls disabled; users with view permissions: root; groups with view permissions: EMPTY; users with modify permissions: root; groups with modify permissions: EMPTY","logger":"airflow.task.hooks.airflow.providers.ssh.hooks.ssh.SSHHook","filename":"ssh.py","lineno":500}
{"timestamp":"2026-04-25T05:45:29.789626Z","level":"warning","event":"26/04/25 14:45:29 INFO Client: Submitting application application_1773931628321_0087 to ResourceManager","logger":"airflow.task.hooks.airflow.providers.ssh.hooks.ssh.SSHHook","filename":"ssh.py","lineno":500}
{"timestamp":"2026-04-25T05:45:30.035627Z","level":"warning","event":"26/04/25 14:45:30 INFO YarnClientImpl: Submitted application application_1773931628321_0087","logger":"airflow.task.hooks.airflow.providers.ssh.hooks.ssh.SSHHook","filename":"ssh.py","lineno":500}
{"timestamp":"2026-04-25T05:45:31.045901Z","level":"warning","event":"26/04/25 14:45:31 INFO Client: Application report for application_1773931628321_0087 (state: ACCEPTED)","logger":"airflow.task.hooks.airflow.providers.ssh.hooks.ssh.SSHHook","filename":"ssh.py","lineno":500}
{"timestamp":"2026-04-25T05:45:31.056753Z","level":"warning","event":"26/04/25 14:45:31 INFO Client: ","logger":"airflow.task.hooks.airflow.providers.ssh.hooks.ssh.SSHHook","filename":"ssh.py","lineno":500}
{"timestamp":"2026-04-25T05:45:31.056981Z","level":"warning","event":"\t client token: N/A","logger":"airflow.task.hooks.airflow.providers.ssh.hooks.ssh.SSHHook","filename":"ssh.py","lineno":500}
{"timestamp":"2026-04-25T05:45:31.057115Z","level":"warning","event":"\t diagnostics: AM container is launched, waiting for AM container to Register with RM","logger":"airflow.task.hooks.airflow.providers.ssh.hooks.ssh.SSHHook","filename":"ssh.py","lineno":500}
{"timestamp":"2026-04-25T05:45:31.057231Z","level":"warning","event":"\t ApplicationMaster host: N/A","logger":"airflow.task.hooks.airflow.providers.ssh.hooks.ssh.SSHHook","filename":"ssh.py","lineno":500}
{"timestamp":"2026-04-25T05:45:31.057336Z","level":"warning","event":"\t ApplicationMaster RPC port: -1","logger":"airflow.task.hooks.airflow.providers.ssh.hooks.ssh.SSHHook","filename":"ssh.py","lineno":500}
{"timestamp":"2026-04-25T05:45:31.057435Z","level":"warning","event":"\t queue: root.root","logger":"airflow.task.hooks.airflow.providers.ssh.hooks.ssh.SSHHook","filename":"ssh.py","lineno":500}
{"timestamp":"2026-04-25T05:45:31.057534Z","level":"warning","event":"\t start time: 1777095929804","logger":"airflow.task.hooks.airflow.providers.ssh.hooks.ssh.SSHHook","filename":"ssh.py","lineno":500}
{"timestamp":"2026-04-25T05:45:31.057631Z","level":"warning","event":"\t final status: UNDEFINED","logger":"airflow.task.hooks.airflow.providers.ssh.hooks.ssh.SSHHook","filename":"ssh.py","lineno":500}
{"timestamp":"2026-04-25T05:45:31.057728Z","level":"warning","event":"\t tracking URL: http://m2:8088/proxy/application_1773931628321_0087/","logger":"airflow.task.hooks.airflow.providers.ssh.hooks.ssh.SSHHook","filename":"ssh.py","lineno":500}
{"timestamp":"2026-04-25T05:45:31.057824Z","level":"warning","event":"\t user: root","logger":"airflow.task.hooks.airflow.providers.ssh.hooks.ssh.SSHHook","filename":"ssh.py","lineno":500}
{"timestamp":"2026-04-25T05:45:32.060431Z","level":"warning","event":"26/04/25 14:45:32 INFO Client: Application report for application_1773931628321_0087 (state: ACCEPTED)","logger":"airflow.task.hooks.airflow.providers.ssh.hooks.ssh.SSHHook","filename":"ssh.py","lineno":500}
{"timestamp":"2026-04-25T05:45:33.102001Z","level":"warning","event":"26/04/25 14:45:33 INFO Client: Application report for application_1773931628321_0087 (state: ACCEPTED)","logger":"airflow.task.hooks.airflow.providers.ssh.hooks.ssh.SSHHook","filename":"ssh.py","lineno":500}
{"timestamp":"2026-04-25T05:45:34.105878Z","level":"warning","event":"26/04/25 14:45:34 INFO Client: Application report for application_1773931628321_0087 (state: ACCEPTED)","logger":"airflow.task.hooks.airflow.providers.ssh.hooks.ssh.SSHHook","filename":"ssh.py","lineno":500}
{"timestamp":"2026-04-25T05:45:35.109242Z","level":"warning","event":"26/04/25 14:45:35 INFO Client: Application report for application_1773931628321_0087 (state: ACCEPTED)","logger":"airflow.task.hooks.airflow.providers.ssh.hooks.ssh.SSHHook","filename":"ssh.py","lineno":500}
{"timestamp":"2026-04-25T05:45:36.113213Z","level":"warning","event":"26/04/25 14:45:36 INFO Client: Application report for application_1773931628321_0087 (state: ACCEPTED)","logger":"airflow.task.hooks.airflow.providers.ssh.hooks.ssh.SSHHook","filename":"ssh.py","lineno":500}
{"timestamp":"2026-04-25T05:45:37.116658Z","level":"warning","event":"26/04/25 14:45:37 INFO Client: Application report for application_1773931628321_0087 (state: ACCEPTED)","logger":"airflow.task.hooks.airflow.providers.ssh.hooks.ssh.SSHHook","filename":"ssh.py","lineno":500}
{"timestamp":"2026-04-25T05:45:38.121344Z","level":"warning","event":"26/04/25 14:45:38 INFO Client: Application report for application_1773931628321_0087 (state: ACCEPTED)","logger":"airflow.task.hooks.airflow.providers.ssh.hooks.ssh.SSHHook","filename":"ssh.py","lineno":500}
{"timestamp":"2026-04-25T05:45:39.124215Z","level":"warning","event":"26/04/25 14:45:39 INFO Client: Application report for application_1773931628321_0087 (state: ACCEPTED)","logger":"airflow.task.hooks.airflow.providers.ssh.hooks.ssh.SSHHook","filename":"ssh.py","lineno":500}
{"timestamp":"2026-04-25T05:45:40.131558Z","level":"warning","event":"26/04/25 14:45:40 INFO Client: Application report for application_1773931628321_0087 (state: RUNNING)","logger":"airflow.task.hooks.airflow.providers.ssh.hooks.ssh.SSHHook","filename":"ssh.py","lineno":500}
{"timestamp":"2026-04-25T05:45:40.131791Z","level":"warning","event":"26/04/25 14:45:40 INFO Client: ","logger":"airflow.task.hooks.airflow.providers.ssh.hooks.ssh.SSHHook","filename":"ssh.py","lineno":500}
{"timestamp":"2026-04-25T05:45:40.131871Z","level":"warning","event":"\t client token: N/A","logger":"airflow.task.hooks.airflow.providers.ssh.hooks.ssh.SSHHook","filename":"ssh.py","lineno":500}
{"timestamp":"2026-04-25T05:45:40.131957Z","level":"warning","event":"\t diagnostics: N/A","logger":"airflow.task.hooks.airflow.providers.ssh.hooks.ssh.SSHHook","filename":"ssh.py","lineno":500}
{"timestamp":"2026-04-25T05:45:40.132017Z","level":"warning","event":"\t ApplicationMaster host: 192.168.122.65","logger":"airflow.task.hooks.airflow.providers.ssh.hooks.ssh.SSHHook","filename":"ssh.py","lineno":500}
{"timestamp":"2026-04-25T05:45:40.132098Z","level":"warning","event":"\t ApplicationMaster RPC port: -1","logger":"airflow.task.hooks.airflow.providers.ssh.hooks.ssh.SSHHook","filename":"ssh.py","lineno":500}
{"timestamp":"2026-04-25T05:45:40.132192Z","level":"warning","event":"\t queue: root.root","logger":"airflow.task.hooks.airflow.providers.ssh.hooks.ssh.SSHHook","filename":"ssh.py","lineno":500}
{"timestamp":"2026-04-25T05:45:40.132250Z","level":"warning","event":"\t start time: 1777095929804","logger":"airflow.task.hooks.airflow.providers.ssh.hooks.ssh.SSHHook","filename":"ssh.py","lineno":500}
{"timestamp":"2026-04-25T05:45:40.132305Z","level":"warning","event":"\t final status: UNDEFINED","logger":"airflow.task.hooks.airflow.providers.ssh.hooks.ssh.SSHHook","filename":"ssh.py","lineno":500}
{"timestamp":"2026-04-25T05:45:40.132358Z","level":"warning","event":"\t tracking URL: http://m2:8088/proxy/application_1773931628321_0087/","logger":"airflow.task.hooks.airflow.providers.ssh.hooks.ssh.SSHHook","filename":"ssh.py","lineno":500}
{"timestamp":"2026-04-25T05:45:40.132430Z","level":"warning","event":"\t user: root","logger":"airflow.task.hooks.airflow.providers.ssh.hooks.ssh.SSHHook","filename":"ssh.py","lineno":500}
{"timestamp":"2026-04-25T05:45:40.132502Z","level":"warning","event":"26/04/25 14:45:40 INFO YarnClientSchedulerBackend: Application application_1773931628321_0087 has started running.","logger":"airflow.task.hooks.airflow.providers.ssh.hooks.ssh.SSHHook","filename":"ssh.py","lineno":500}
{"timestamp":"2026-04-25T05:45:40.150327Z","level":"warning","event":"26/04/25 14:45:40 INFO Utils: Successfully started service 'org.apache.spark.network.netty.NettyBlockTransferService' on port 37699.","logger":"airflow.task.hooks.airflow.providers.ssh.hooks.ssh.SSHHook","filename":"ssh.py","lineno":500}
{"timestamp":"2026-04-25T05:45:40.151140Z","level":"warning","event":"26/04/25 14:45:40 INFO NettyBlockTransferService: Server created on ap:37699","logger":"airflow.task.hooks.airflow.providers.ssh.hooks.ssh.SSHHook","filename":"ssh.py","lineno":500}
{"timestamp":"2026-04-25T05:45:40.155659Z","level":"warning","event":"26/04/25 14:45:40 INFO BlockManager: Using org.apache.spark.storage.RandomBlockReplicationPolicy for block replication policy","logger":"airflow.task.hooks.airflow.providers.ssh.hooks.ssh.SSHHook","filename":"ssh.py","lineno":500}
{"timestamp":"2026-04-25T05:45:40.186810Z","level":"warning","event":"26/04/25 14:45:40 INFO BlockManagerMaster: Registering BlockManager BlockManagerId(driver, ap, 37699, None)","logger":"airflow.task.hooks.airflow.providers.ssh.hooks.ssh.SSHHook","filename":"ssh.py","lineno":500}
{"timestamp":"2026-04-25T05:45:40.193305Z","level":"warning","event":"26/04/25 14:45:40 INFO BlockManagerMasterEndpoint: Registering block manager ap:37699 with 2.2 GiB RAM, BlockManagerId(driver, ap, 37699, None)","logger":"airflow.task.hooks.airflow.providers.ssh.hooks.ssh.SSHHook","filename":"ssh.py","lineno":500}
{"timestamp":"2026-04-25T05:45:40.203805Z","level":"warning","event":"26/04/25 14:45:40 INFO BlockManagerMaster: Registered BlockManager BlockManagerId(driver, ap, 37699, None)","logger":"airflow.task.hooks.airflow.providers.ssh.hooks.ssh.SSHHook","filename":"ssh.py","lineno":500}
{"timestamp":"2026-04-25T05:45:40.205416Z","level":"warning","event":"26/04/25 14:45:40 INFO BlockManager: Initialized BlockManager: BlockManagerId(driver, ap, 37699, None)","logger":"airflow.task.hooks.airflow.providers.ssh.hooks.ssh.SSHHook","filename":"ssh.py","lineno":500}
{"timestamp":"2026-04-25T05:45:40.229007Z","level":"warning","event":"26/04/25 14:45:40 INFO YarnClientSchedulerBackend: Add WebUI Filter. org.apache.hadoop.yarn.server.webproxy.amfilter.AmIpFilter, Map(PROXY_HOSTS -> m1,m2, PROXY_URI_BASES -> http://m1:8088/proxy/application_1773931628321_0087,http://m2:8088/proxy/application_1773931628321_0087, RM_HA_URLS -> m1:8088,m2:8088), /proxy/application_1773931628321_0087","logger":"airflow.task.hooks.airflow.providers.ssh.hooks.ssh.SSHHook","filename":"ssh.py","lineno":500}
{"timestamp":"2026-04-25T05:45:40.653537Z","level":"warning","event":"26/04/25 14:45:40 INFO ServerInfo: Adding filter to /jobs: org.apache.hadoop.yarn.server.webproxy.amfilter.AmIpFilter","logger":"airflow.task.hooks.airflow.providers.ssh.hooks.ssh.SSHHook","filename":"ssh.py","lineno":500}
{"timestamp":"2026-04-25T05:45:40.665339Z","level":"warning","event":"26/04/25 14:45:40 INFO ServerInfo: Adding filter to /jobs/json: org.apache.hadoop.yarn.server.webproxy.amfilter.AmIpFilter","logger":"airflow.task.hooks.airflow.providers.ssh.hooks.ssh.SSHHook","filename":"ssh.py","lineno":500}
{"timestamp":"2026-04-25T05:45:40.667865Z","level":"warning","event":"26/04/25 14:45:40 INFO ServerInfo: Adding filter to /jobs/job: org.apache.hadoop.yarn.server.webproxy.amfilter.AmIpFilter","logger":"airflow.task.hooks.airflow.providers.ssh.hooks.ssh.SSHHook","filename":"ssh.py","lineno":500}
{"timestamp":"2026-04-25T05:45:40.671283Z","level":"warning","event":"26/04/25 14:45:40 INFO ServerInfo: Adding filter to /jobs/job/json: org.apache.hadoop.yarn.server.webproxy.amfilter.AmIpFilter","logger":"airflow.task.hooks.airflow.providers.ssh.hooks.ssh.SSHHook","filename":"ssh.py","lineno":500}
{"timestamp":"2026-04-25T05:45:40.673924Z","level":"warning","event":"26/04/25 14:45:40 INFO ServerInfo: Adding filter to /stages: org.apache.hadoop.yarn.server.webproxy.amfilter.AmIpFilter","logger":"airflow.task.hooks.airflow.providers.ssh.hooks.ssh.SSHHook","filename":"ssh.py","lineno":500}
{"timestamp":"2026-04-25T05:45:40.676678Z","level":"warning","event":"26/04/25 14:45:40 INFO ServerInfo: Adding filter to /stages/json: org.apache.hadoop.yarn.server.webproxy.amfilter.AmIpFilter","logger":"airflow.task.hooks.airflow.providers.ssh.hooks.ssh.SSHHook","filename":"ssh.py","lineno":500}
{"timestamp":"2026-04-25T05:45:40.679330Z","level":"warning","event":"26/04/25 14:45:40 INFO ServerInfo: Adding filter to /stages/stage: org.apache.hadoop.yarn.server.webproxy.amfilter.AmIpFilter","logger":"airflow.task.hooks.airflow.providers.ssh.hooks.ssh.SSHHook","filename":"ssh.py","lineno":500}
{"timestamp":"2026-04-25T05:45:40.683068Z","level":"warning","event":"26/04/25 14:45:40 INFO ServerInfo: Adding filter to /stages/stage/json: org.apache.hadoop.yarn.server.webproxy.amfilter.AmIpFilter","logger":"airflow.task.hooks.airflow.providers.ssh.hooks.ssh.SSHHook","filename":"ssh.py","lineno":500}
{"timestamp":"2026-04-25T05:45:40.686194Z","level":"warning","event":"26/04/25 14:45:40 INFO ServerInfo: Adding filter to /stages/pool: org.apache.hadoop.yarn.server.webproxy.amfilter.AmIpFilter","logger":"airflow.task.hooks.airflow.providers.ssh.hooks.ssh.SSHHook","filename":"ssh.py","lineno":500}
{"timestamp":"2026-04-25T05:45:40.688861Z","level":"warning","event":"26/04/25 14:45:40 INFO ServerInfo: Adding filter to /stages/pool/json: org.apache.hadoop.yarn.server.webproxy.amfilter.AmIpFilter","logger":"airflow.task.hooks.airflow.providers.ssh.hooks.ssh.SSHHook","filename":"ssh.py","lineno":500}
{"timestamp":"2026-04-25T05:45:40.691914Z","level":"warning","event":"26/04/25 14:45:40 INFO ServerInfo: Adding filter to /storage: org.apache.hadoop.yarn.server.webproxy.amfilter.AmIpFilter","logger":"airflow.task.hooks.airflow.providers.ssh.hooks.ssh.SSHHook","filename":"ssh.py","lineno":500}
{"timestamp":"2026-04-25T05:45:40.694650Z","level":"warning","event":"26/04/25 14:45:40 INFO ServerInfo: Adding filter to /storage/json: org.apache.hadoop.yarn.server.webproxy.amfilter.AmIpFilter","logger":"airflow.task.hooks.airflow.providers.ssh.hooks.ssh.SSHHook","filename":"ssh.py","lineno":500}
{"timestamp":"2026-04-25T05:45:40.697405Z","level":"warning","event":"26/04/25 14:45:40 INFO ServerInfo: Adding filter to /storage/rdd: org.apache.hadoop.yarn.server.webproxy.amfilter.AmIpFilter","logger":"airflow.task.hooks.airflow.providers.ssh.hooks.ssh.SSHHook","filename":"ssh.py","lineno":500}
{"timestamp":"2026-04-25T05:45:40.700030Z","level":"warning","event":"26/04/25 14:45:40 INFO ServerInfo: Adding filter to /storage/rdd/json: org.apache.hadoop.yarn.server.webproxy.amfilter.AmIpFilter","logger":"airflow.task.hooks.airflow.providers.ssh.hooks.ssh.SSHHook","filename":"ssh.py","lineno":500}
{"timestamp":"2026-04-25T05:45:40.702682Z","level":"warning","event":"26/04/25 14:45:40 INFO ServerInfo: Adding filter to /environment: org.apache.hadoop.yarn.server.webproxy.amfilter.AmIpFilter","logger":"airflow.task.hooks.airflow.providers.ssh.hooks.ssh.SSHHook","filename":"ssh.py","lineno":500}
{"timestamp":"2026-04-25T05:45:40.705333Z","level":"warning","event":"26/04/25 14:45:40 INFO ServerInfo: Adding filter to /environment/json: org.apache.hadoop.yarn.server.webproxy.amfilter.AmIpFilter","logger":"airflow.task.hooks.airflow.providers.ssh.hooks.ssh.SSHHook","filename":"ssh.py","lineno":500}
{"timestamp":"2026-04-25T05:45:40.708146Z","level":"warning","event":"26/04/25 14:45:40 INFO ServerInfo: Adding filter to /executors: org.apache.hadoop.yarn.server.webproxy.amfilter.AmIpFilter","logger":"airflow.task.hooks.airflow.providers.ssh.hooks.ssh.SSHHook","filename":"ssh.py","lineno":500}
{"timestamp":"2026-04-25T05:45:40.710794Z","level":"warning","event":"26/04/25 14:45:40 INFO ServerInfo: Adding filter to /executors/json: org.apache.hadoop.yarn.server.webproxy.amfilter.AmIpFilter","logger":"airflow.task.hooks.airflow.providers.ssh.hooks.ssh.SSHHook","filename":"ssh.py","lineno":500}
{"timestamp":"2026-04-25T05:45:40.713453Z","level":"warning","event":"26/04/25 14:45:40 INFO ServerInfo: Adding filter to /executors/threadDump: org.apache.hadoop.yarn.server.webproxy.amfilter.AmIpFilter","logger":"airflow.task.hooks.airflow.providers.ssh.hooks.ssh.SSHHook","filename":"ssh.py","lineno":500}
{"timestamp":"2026-04-25T05:45:40.717089Z","level":"warning","event":"26/04/25 14:45:40 INFO ServerInfo: Adding filter to /executors/threadDump/json: org.apache.hadoop.yarn.server.webproxy.amfilter.AmIpFilter","logger":"airflow.task.hooks.airflow.providers.ssh.hooks.ssh.SSHHook","filename":"ssh.py","lineno":500}
{"timestamp":"2026-04-25T05:45:40.720197Z","level":"warning","event":"26/04/25 14:45:40 INFO ServerInfo: Adding filter to /static: org.apache.hadoop.yarn.server.webproxy.amfilter.AmIpFilter","logger":"airflow.task.hooks.airflow.providers.ssh.hooks.ssh.SSHHook","filename":"ssh.py","lineno":500}
{"timestamp":"2026-04-25T05:45:40.747762Z","level":"warning","event":"26/04/25 14:45:40 INFO YarnSchedulerBackend$YarnSchedulerEndpoint: ApplicationMaster registered as NettyRpcEndpointRef(spark-client://YarnAM)","logger":"airflow.task.hooks.airflow.providers.ssh.hooks.ssh.SSHHook","filename":"ssh.py","lineno":500}
{"timestamp":"2026-04-25T05:45:40.758520Z","level":"warning","event":"26/04/25 14:45:40 INFO ServerInfo: Adding filter to /: org.apache.hadoop.yarn.server.webproxy.amfilter.AmIpFilter","logger":"airflow.task.hooks.airflow.providers.ssh.hooks.ssh.SSHHook","filename":"ssh.py","lineno":500}
{"timestamp":"2026-04-25T05:45:40.760557Z","level":"warning","event":"26/04/25 14:45:40 INFO ServerInfo: Adding filter to /api: org.apache.hadoop.yarn.server.webproxy.amfilter.AmIpFilter","logger":"airflow.task.hooks.airflow.providers.ssh.hooks.ssh.SSHHook","filename":"ssh.py","lineno":500}
{"timestamp":"2026-04-25T05:45:40.764633Z","level":"warning","event":"26/04/25 14:45:40 INFO ServerInfo: Adding filter to /jobs/job/kill: org.apache.hadoop.yarn.server.webproxy.amfilter.AmIpFilter","logger":"airflow.task.hooks.airflow.providers.ssh.hooks.ssh.SSHHook","filename":"ssh.py","lineno":500}
{"timestamp":"2026-04-25T05:45:40.766634Z","level":"warning","event":"26/04/25 14:45:40 INFO ServerInfo: Adding filter to /stages/stage/kill: org.apache.hadoop.yarn.server.webproxy.amfilter.AmIpFilter","logger":"airflow.task.hooks.airflow.providers.ssh.hooks.ssh.SSHHook","filename":"ssh.py","lineno":500}
{"timestamp":"2026-04-25T05:45:40.773954Z","level":"warning","event":"26/04/25 14:45:40 INFO ServerInfo: Adding filter to /metrics/json: org.apache.hadoop.yarn.server.webproxy.amfilter.AmIpFilter","logger":"airflow.task.hooks.airflow.providers.ssh.hooks.ssh.SSHHook","filename":"ssh.py","lineno":500}
{"timestamp":"2026-04-25T05:45:46.707627Z","level":"warning","event":"26/04/25 14:45:46 INFO YarnSchedulerBackend$YarnDriverEndpoint: Registered executor NettyRpcEndpointRef(spark-client://Executor) (192.168.122.65:56384) with ID 1,  ResourceProfileId 0","logger":"airflow.task.hooks.airflow.providers.ssh.hooks.ssh.SSHHook","filename":"ssh.py","lineno":500}
{"timestamp":"2026-04-25T05:45:46.916892Z","level":"warning","event":"26/04/25 14:45:46 INFO BlockManagerMasterEndpoint: Registering block manager s1:40843 with 912.3 MiB RAM, BlockManagerId(1, s1, 40843, None)","logger":"airflow.task.hooks.airflow.providers.ssh.hooks.ssh.SSHHook","filename":"ssh.py","lineno":500}
{"timestamp":"2026-04-25T05:45:50.307668Z","level":"warning","event":"26/04/25 14:45:50 INFO YarnClientSchedulerBackend: SchedulerBackend is ready for scheduling beginning after waiting maxRegisteredResourcesWaitingTime: 30000000000(ns)","logger":"airflow.task.hooks.airflow.providers.ssh.hooks.ssh.SSHHook","filename":"ssh.py","lineno":500}
{"timestamp":"2026-04-25T05:45:50.663205Z","level":"warning","event":"26/04/25 14:45:50 INFO SharedState: spark.sql.warehouse.dir is not set, but hive.metastore.warehouse.dir is set. Setting spark.sql.warehouse.dir to the value of hive.metastore.warehouse.dir.","logger":"airflow.task.hooks.airflow.providers.ssh.hooks.ssh.SSHHook","filename":"ssh.py","lineno":500}
{"timestamp":"2026-04-25T05:45:50.669217Z","level":"warning","event":"26/04/25 14:45:50 INFO SharedState: Warehouse path is 'hdfs://job-cluster/hive'.","logger":"airflow.task.hooks.airflow.providers.ssh.hooks.ssh.SSHHook","filename":"ssh.py","lineno":500}
{"timestamp":"2026-04-25T05:45:50.690934Z","level":"warning","event":"26/04/25 14:45:50 INFO ServerInfo: Adding filter to /SQL: org.apache.hadoop.yarn.server.webproxy.amfilter.AmIpFilter","logger":"airflow.task.hooks.airflow.providers.ssh.hooks.ssh.SSHHook","filename":"ssh.py","lineno":500}
{"timestamp":"2026-04-25T05:45:50.694580Z","level":"warning","event":"26/04/25 14:45:50 INFO ServerInfo: Adding filter to /SQL/json: org.apache.hadoop.yarn.server.webproxy.amfilter.AmIpFilter","logger":"airflow.task.hooks.airflow.providers.ssh.hooks.ssh.SSHHook","filename":"ssh.py","lineno":500}
{"timestamp":"2026-04-25T05:45:50.696762Z","level":"warning","event":"26/04/25 14:45:50 INFO ServerInfo: Adding filter to /SQL/execution: org.apache.hadoop.yarn.server.webproxy.amfilter.AmIpFilter","logger":"airflow.task.hooks.airflow.providers.ssh.hooks.ssh.SSHHook","filename":"ssh.py","lineno":500}
{"timestamp":"2026-04-25T05:45:50.698630Z","level":"warning","event":"26/04/25 14:45:50 INFO ServerInfo: Adding filter to /SQL/execution/json: org.apache.hadoop.yarn.server.webproxy.amfilter.AmIpFilter","logger":"airflow.task.hooks.airflow.providers.ssh.hooks.ssh.SSHHook","filename":"ssh.py","lineno":500}
{"timestamp":"2026-04-25T05:45:50.702487Z","level":"warning","event":"26/04/25 14:45:50 INFO ServerInfo: Adding filter to /static/sql: org.apache.hadoop.yarn.server.webproxy.amfilter.AmIpFilter","logger":"airflow.task.hooks.airflow.providers.ssh.hooks.ssh.SSHHook","filename":"ssh.py","lineno":500}
{"timestamp":"2026-04-25T05:45:52.353188Z","level":"warning","event":"26/04/25 14:45:52 INFO YarnSchedulerBackend$YarnDriverEndpoint: Registered executor NettyRpcEndpointRef(spark-client://Executor) (192.168.122.64:49504) with ID 2,  ResourceProfileId 0","logger":"airflow.task.hooks.airflow.providers.ssh.hooks.ssh.SSHHook","filename":"ssh.py","lineno":500}
{"timestamp":"2026-04-25T05:45:52.477461Z","level":"warning","event":"26/04/25 14:45:52 INFO BlockManagerMasterEndpoint: Registering block manager m2:38991 with 912.3 MiB RAM, BlockManagerId(2, m2, 38991, None)","logger":"airflow.task.hooks.airflow.providers.ssh.hooks.ssh.SSHHook","filename":"ssh.py","lineno":500}
{"timestamp":"2026-04-25T05:45:53.076527Z","level":"warning","event":"26/04/25 14:45:53 INFO HiveConf: Found configuration file file:/application/spark-3.4.3-bin-hadoop3/conf/hive-site.xml","logger":"airflow.task.hooks.airflow.providers.ssh.hooks.ssh.SSHHook","filename":"ssh.py","lineno":500}
{"timestamp":"2026-04-25T05:45:53.092316Z","level":"warning","event":"26/04/25 14:45:53 INFO HiveUtils: Initializing HiveMetastoreConnection version 2.3.9 using Spark classes.","logger":"airflow.task.hooks.airflow.providers.ssh.hooks.ssh.SSHHook","filename":"ssh.py","lineno":500}
{"timestamp":"2026-04-25T05:45:53.311562Z","level":"warning","event":"26/04/25 14:45:53 WARN HiveConf: HiveConf of name hive.metastore.db.type does not exist","logger":"airflow.task.hooks.airflow.providers.ssh.hooks.ssh.SSHHook","filename":"ssh.py","lineno":500}
{"timestamp":"2026-04-25T05:45:53.412265Z","level":"warning","event":"26/04/25 14:45:53 INFO HiveClientImpl: Warehouse location for Hive client (version 2.3.9) is hdfs://job-cluster/hive","logger":"airflow.task.hooks.airflow.providers.ssh.hooks.ssh.SSHHook","filename":"ssh.py","lineno":500}
{"timestamp":"2026-04-25T05:45:53.603451Z","level":"warning","event":"26/04/25 14:45:53 WARN HiveConf: HiveConf of name hive.stats.jdbc.timeout does not exist","logger":"airflow.task.hooks.airflow.providers.ssh.hooks.ssh.SSHHook","filename":"ssh.py","lineno":500}
{"timestamp":"2026-04-25T05:45:53.604268Z","level":"warning","event":"26/04/25 14:45:53 WARN HiveConf: HiveConf of name hive.metastore.db.type does not exist","logger":"airflow.task.hooks.airflow.providers.ssh.hooks.ssh.SSHHook","filename":"ssh.py","lineno":500}
{"timestamp":"2026-04-25T05:45:53.604359Z","level":"warning","event":"26/04/25 14:45:53 WARN HiveConf: HiveConf of name hive.stats.retries.wait does not exist","logger":"airflow.task.hooks.airflow.providers.ssh.hooks.ssh.SSHHook","filename":"ssh.py","lineno":500}
{"timestamp":"2026-04-25T05:45:53.604432Z","level":"warning","event":"26/04/25 14:45:53 INFO HiveMetaStore: 0: Opening raw store with implementation class:org.apache.hadoop.hive.metastore.ObjectStore","logger":"airflow.task.hooks.airflow.providers.ssh.hooks.ssh.SSHHook","filename":"ssh.py","lineno":500}
{"timestamp":"2026-04-25T05:45:53.712791Z","level":"warning","event":"26/04/25 14:45:53 INFO ObjectStore: ObjectStore, initialize called","logger":"airflow.task.hooks.airflow.providers.ssh.hooks.ssh.SSHHook","filename":"ssh.py","lineno":500}
{"timestamp":"2026-04-25T05:45:54.119180Z","level":"warning","event":"26/04/25 14:45:54 INFO Persistence: Property hive.metastore.integral.jdo.pushdown unknown - will be ignored","logger":"airflow.task.hooks.airflow.providers.ssh.hooks.ssh.SSHHook","filename":"ssh.py","lineno":500}
{"timestamp":"2026-04-25T05:45:54.120280Z","level":"warning","event":"26/04/25 14:45:54 INFO Persistence: Property datanucleus.cache.level2 unknown - will be ignored","logger":"airflow.task.hooks.airflow.providers.ssh.hooks.ssh.SSHHook","filename":"ssh.py","lineno":500}
{"timestamp":"2026-04-25T05:45:55.246955Z","level":"warning","event":"26/04/25 14:45:55 WARN HiveConf: HiveConf of name hive.metastore.db.type does not exist","logger":"airflow.task.hooks.airflow.providers.ssh.hooks.ssh.SSHHook","filename":"ssh.py","lineno":500}
{"timestamp":"2026-04-25T05:45:55.248006Z","level":"warning","event":"26/04/25 14:45:55 INFO ObjectStore: Setting MetaStore object pin classes with hive.metastore.cache.pinobjtypes=\"Table,StorageDescriptor,SerDeInfo,Partition,Database,Type,FieldSchema,Order\"","logger":"airflow.task.hooks.airflow.providers.ssh.hooks.ssh.SSHHook","filename":"ssh.py","lineno":500}
{"timestamp":"2026-04-25T05:45:56.297171Z","level":"warning","event":"26/04/25 14:45:56 INFO MetaStoreDirectSql: Using direct SQL, underlying DB is POSTGRES","logger":"airflow.task.hooks.airflow.providers.ssh.hooks.ssh.SSHHook","filename":"ssh.py","lineno":500}
{"timestamp":"2026-04-25T05:45:56.301153Z","level":"warning","event":"26/04/25 14:45:56 INFO ObjectStore: Initialized ObjectStore","logger":"airflow.task.hooks.airflow.providers.ssh.hooks.ssh.SSHHook","filename":"ssh.py","lineno":500}
{"timestamp":"2026-04-25T05:45:56.432465Z","level":"warning","event":"26/04/25 14:45:56 INFO HiveMetaStore: Added admin role in metastore","logger":"airflow.task.hooks.airflow.providers.ssh.hooks.ssh.SSHHook","filename":"ssh.py","lineno":500}
{"timestamp":"2026-04-25T05:45:56.435046Z","level":"warning","event":"26/04/25 14:45:56 INFO HiveMetaStore: Added public role in metastore","logger":"airflow.task.hooks.airflow.providers.ssh.hooks.ssh.SSHHook","filename":"ssh.py","lineno":500}
{"timestamp":"2026-04-25T05:45:56.454243Z","level":"warning","event":"26/04/25 14:45:56 INFO HiveMetaStore: No user is added in admin role, since config is empty","logger":"airflow.task.hooks.airflow.providers.ssh.hooks.ssh.SSHHook","filename":"ssh.py","lineno":500}
{"timestamp":"2026-04-25T05:45:56.613742Z","level":"warning","event":"26/04/25 14:45:56 INFO HiveMetaStore: 0: get_database: default","logger":"airflow.task.hooks.airflow.providers.ssh.hooks.ssh.SSHHook","filename":"ssh.py","lineno":500}
{"timestamp":"2026-04-25T05:45:56.617142Z","level":"warning","event":"26/04/25 14:45:56 INFO audit: ugi=root\tip=unknown-ip-addr\tcmd=get_database: default\t","logger":"airflow.task.hooks.airflow.providers.ssh.hooks.ssh.SSHHook","filename":"ssh.py","lineno":500}
{"timestamp":"2026-04-25T05:45:56.625362Z","level":"warning","event":"26/04/25 14:45:56 INFO HiveMetaStore: 0: get_database: default","logger":"airflow.task.hooks.airflow.providers.ssh.hooks.ssh.SSHHook","filename":"ssh.py","lineno":500}
{"timestamp":"2026-04-25T05:45:56.627358Z","level":"warning","event":"26/04/25 14:45:56 INFO audit: ugi=root\tip=unknown-ip-addr\tcmd=get_database: default\t","logger":"airflow.task.hooks.airflow.providers.ssh.hooks.ssh.SSHHook","filename":"ssh.py","lineno":500}
{"timestamp":"2026-04-25T05:45:56.633025Z","level":"warning","event":"26/04/25 14:45:56 INFO HiveMetaStore: 0: get_table : db=default tbl=staging","logger":"airflow.task.hooks.airflow.providers.ssh.hooks.ssh.SSHHook","filename":"ssh.py","lineno":500}
{"timestamp":"2026-04-25T05:45:56.633688Z","level":"warning","event":"26/04/25 14:45:56 INFO audit: ugi=root\tip=unknown-ip-addr\tcmd=get_table : db=default tbl=staging\t","logger":"airflow.task.hooks.airflow.providers.ssh.hooks.ssh.SSHHook","filename":"ssh.py","lineno":500}
{"timestamp":"2026-04-25T05:45:56.735670Z","level":"warning","event":"26/04/25 14:45:56 INFO HiveMetaStore: 0: get_table : db=default tbl=staging","logger":"airflow.task.hooks.airflow.providers.ssh.hooks.ssh.SSHHook","filename":"ssh.py","lineno":500}
{"timestamp":"2026-04-25T05:45:56.736572Z","level":"warning","event":"26/04/25 14:45:56 INFO audit: ugi=root\tip=unknown-ip-addr\tcmd=get_table : db=default tbl=staging\t","logger":"airflow.task.hooks.airflow.providers.ssh.hooks.ssh.SSHHook","filename":"ssh.py","lineno":500}
{"timestamp":"2026-04-25T05:46:01.269829Z","level":"warning","event":"26/04/25 14:46:01 INFO CodeGenerator: Code generated in 388.780047 ms","logger":"airflow.task.hooks.airflow.providers.ssh.hooks.ssh.SSHHook","filename":"ssh.py","lineno":500}
{"timestamp":"2026-04-25T05:46:01.319633Z","level":"warning","event":"26/04/25 14:46:01 INFO SQLStdHiveAccessController: Created SQLStdHiveAccessController for session context : HiveAuthzSessionContext [sessionString=7a63fe37-8e17-4bbc-9e60-e975062c0c8b, clientType=HIVECLI]","logger":"airflow.task.hooks.airflow.providers.ssh.hooks.ssh.SSHHook","filename":"ssh.py","lineno":500}
{"timestamp":"2026-04-25T05:46:01.321862Z","level":"warning","event":"26/04/25 14:46:01 WARN SessionState: METASTORE_FILTER_HOOK will be ignored, since hive.security.authorization.manager is set to instance of HiveAuthorizerFactory.","logger":"airflow.task.hooks.airflow.providers.ssh.hooks.ssh.SSHHook","filename":"ssh.py","lineno":500}
{"timestamp":"2026-04-25T05:46:01.322421Z","level":"warning","event":"26/04/25 14:46:01 INFO metastore: Mestastore configuration hive.metastore.filter.hook changed from org.apache.hadoop.hive.metastore.DefaultMetaStoreFilterHookImpl to org.apache.hadoop.hive.ql.security.authorization.plugin.AuthorizationMetaStoreFilterHook","logger":"airflow.task.hooks.airflow.providers.ssh.hooks.ssh.SSHHook","filename":"ssh.py","lineno":500}
{"timestamp":"2026-04-25T05:46:01.324880Z","level":"warning","event":"26/04/25 14:46:01 INFO HiveMetaStore: 0: Cleaning up thread local RawStore...","logger":"airflow.task.hooks.airflow.providers.ssh.hooks.ssh.SSHHook","filename":"ssh.py","lineno":500}
{"timestamp":"2026-04-25T05:46:01.325774Z","level":"warning","event":"26/04/25 14:46:01 INFO audit: ugi=root\tip=unknown-ip-addr\tcmd=Cleaning up thread local RawStore...\t","logger":"airflow.task.hooks.airflow.providers.ssh.hooks.ssh.SSHHook","filename":"ssh.py","lineno":500}
{"timestamp":"2026-04-25T05:46:01.326397Z","level":"warning","event":"26/04/25 14:46:01 INFO HiveMetaStore: 0: Done cleaning up thread local RawStore","logger":"airflow.task.hooks.airflow.providers.ssh.hooks.ssh.SSHHook","filename":"ssh.py","lineno":500}
{"timestamp":"2026-04-25T05:46:01.326856Z","level":"warning","event":"26/04/25 14:46:01 INFO audit: ugi=root\tip=unknown-ip-addr\tcmd=Done cleaning up thread local RawStore\t","logger":"airflow.task.hooks.airflow.providers.ssh.hooks.ssh.SSHHook","filename":"ssh.py","lineno":500}
{"timestamp":"2026-04-25T05:46:01.528767Z","level":"warning","event":"26/04/25 14:46:01 INFO MemoryStore: Block broadcast_0 stored as values in memory (estimated size 207.7 KiB, free 2.2 GiB)","logger":"airflow.task.hooks.airflow.providers.ssh.hooks.ssh.SSHHook","filename":"ssh.py","lineno":500}
{"timestamp":"2026-04-25T05:46:01.596545Z","level":"warning","event":"26/04/25 14:46:01 INFO MemoryStore: Block broadcast_0_piece0 stored as bytes in memory (estimated size 38.1 KiB, free 2.2 GiB)","logger":"airflow.task.hooks.airflow.providers.ssh.hooks.ssh.SSHHook","filename":"ssh.py","lineno":500}
{"timestamp":"2026-04-25T05:46:01.600070Z","level":"warning","event":"26/04/25 14:46:01 INFO BlockManagerInfo: Added broadcast_0_piece0 in memory on ap:37699 (size: 38.1 KiB, free: 2.2 GiB)","logger":"airflow.task.hooks.airflow.providers.ssh.hooks.ssh.SSHHook","filename":"ssh.py","lineno":500}
{"timestamp":"2026-04-25T05:46:01.603640Z","level":"warning","event":"26/04/25 14:46:01 INFO SparkContext: Created broadcast 0 from ","logger":"airflow.task.hooks.airflow.providers.ssh.hooks.ssh.SSHHook","filename":"ssh.py","lineno":500}
{"timestamp":"2026-04-25T05:46:02.122848Z","level":"warning","event":"26/04/25 14:46:02 INFO FileInputFormat: Total input files to process : 892","logger":"airflow.task.hooks.airflow.providers.ssh.hooks.ssh.SSHHook","filename":"ssh.py","lineno":500}
{"timestamp":"2026-04-25T05:46:02.303380Z","level":"warning","event":"26/04/25 14:46:02 INFO DAGScheduler: Registering RDD 5 (collect at /application/airflow/script/spark_validation.py:43) as input to shuffle 0","logger":"airflow.task.hooks.airflow.providers.ssh.hooks.ssh.SSHHook","filename":"ssh.py","lineno":500}
{"timestamp":"2026-04-25T05:46:02.313390Z","level":"warning","event":"26/04/25 14:46:02 INFO DAGScheduler: Got map stage job 0 (collect at /application/airflow/script/spark_validation.py:43) with 892 output partitions","logger":"airflow.task.hooks.airflow.providers.ssh.hooks.ssh.SSHHook","filename":"ssh.py","lineno":500}
{"timestamp":"2026-04-25T05:46:02.314437Z","level":"warning","event":"26/04/25 14:46:02 INFO DAGScheduler: Final stage: ShuffleMapStage 0 (collect at /application/airflow/script/spark_validation.py:43)","logger":"airflow.task.hooks.airflow.providers.ssh.hooks.ssh.SSHHook","filename":"ssh.py","lineno":500}
{"timestamp":"2026-04-25T05:46:02.315498Z","level":"warning","event":"26/04/25 14:46:02 INFO DAGScheduler: Parents of final stage: List()","logger":"airflow.task.hooks.airflow.providers.ssh.hooks.ssh.SSHHook","filename":"ssh.py","lineno":500}
{"timestamp":"2026-04-25T05:46:02.329932Z","level":"warning","event":"26/04/25 14:46:02 INFO DAGScheduler: Missing parents: List()","logger":"airflow.task.hooks.airflow.providers.ssh.hooks.ssh.SSHHook","filename":"ssh.py","lineno":500}
{"timestamp":"2026-04-25T05:46:02.335773Z","level":"warning","event":"26/04/25 14:46:02 INFO DAGScheduler: Submitting ShuffleMapStage 0 (MapPartitionsRDD[5] at collect at /application/airflow/script/spark_validation.py:43), which has no missing parents","logger":"airflow.task.hooks.airflow.providers.ssh.hooks.ssh.SSHHook","filename":"ssh.py","lineno":500}
{"timestamp":"2026-04-25T05:46:02.579173Z","level":"warning","event":"26/04/25 14:46:02 INFO MemoryStore: Block broadcast_1 stored as values in memory (estimated size 17.5 KiB, free 2.2 GiB)","logger":"airflow.task.hooks.airflow.providers.ssh.hooks.ssh.SSHHook","filename":"ssh.py","lineno":500}
{"timestamp":"2026-04-25T05:46:02.591741Z","level":"warning","event":"26/04/25 14:46:02 INFO MemoryStore: Block broadcast_1_piece0 stored as bytes in memory (estimated size 8.6 KiB, free 2.2 GiB)","logger":"airflow.task.hooks.airflow.providers.ssh.hooks.ssh.SSHHook","filename":"ssh.py","lineno":500}
{"timestamp":"2026-04-25T05:46:02.593507Z","level":"warning","event":"26/04/25 14:46:02 INFO BlockManagerInfo: Added broadcast_1_piece0 in memory on ap:37699 (size: 8.6 KiB, free: 2.2 GiB)","logger":"airflow.task.hooks.airflow.providers.ssh.hooks.ssh.SSHHook","filename":"ssh.py","lineno":500}
{"timestamp":"2026-04-25T05:46:02.597213Z","level":"warning","event":"26/04/25 14:46:02 INFO SparkContext: Created broadcast 1 from broadcast at DAGScheduler.scala:1540","logger":"airflow.task.hooks.airflow.providers.ssh.hooks.ssh.SSHHook","filename":"ssh.py","lineno":500}
{"timestamp":"2026-04-25T05:46:02.674110Z","level":"warning","event":"26/04/25 14:46:02 INFO DAGScheduler: Submitting 892 missing tasks from ShuffleMapStage 0 (MapPartitionsRDD[5] at collect at /application/airflow/script/spark_validation.py:43) (first 15 tasks are for partitions Vector(0, 1, 2, 3, 4, 5, 6, 7, 8, 9, 10, 11, 12, 13, 14))","logger":"airflow.task.hooks.airflow.providers.ssh.hooks.ssh.SSHHook","filename":"ssh.py","lineno":500}
{"timestamp":"2026-04-25T05:46:02.677451Z","level":"warning","event":"26/04/25 14:46:02 INFO YarnScheduler: Adding task set 0.0 with 892 tasks resource profile 0","logger":"airflow.task.hooks.airflow.providers.ssh.hooks.ssh.SSHHook","filename":"ssh.py","lineno":500}
{"timestamp":"2026-04-25T05:46:02.798392Z","level":"warning","event":"26/04/25 14:46:02 INFO TaskSetManager: Starting task 0.0 in stage 0.0 (TID 0) (s1, executor 1, partition 0, NODE_LOCAL, 7437 bytes) ","logger":"airflow.task.hooks.airflow.providers.ssh.hooks.ssh.SSHHook","filename":"ssh.py","lineno":500}
{"timestamp":"2026-04-25T05:46:02.802892Z","level":"warning","event":"26/04/25 14:46:02 INFO TaskSetManager: Starting task 1.0 in stage 0.0 (TID 1) (m2, executor 2, partition 1, NODE_LOCAL, 7437 bytes) ","logger":"airflow.task.hooks.airflow.providers.ssh.hooks.ssh.SSHHook","filename":"ssh.py","lineno":500}
{"timestamp":"2026-04-25T05:46:03.199731Z","level":"warning","event":"26/04/25 14:46:03 INFO BlockManagerInfo: Added broadcast_1_piece0 in memory on s1:40843 (size: 8.6 KiB, free: 912.3 MiB)","logger":"airflow.task.hooks.airflow.providers.ssh.hooks.ssh.SSHHook","filename":"ssh.py","lineno":500}
{"timestamp":"2026-04-25T05:46:03.203446Z","level":"warning","event":"26/04/25 14:46:03 INFO BlockManagerInfo: Added broadcast_1_piece0 in memory on m2:38991 (size: 8.6 KiB, free: 912.3 MiB)","logger":"airflow.task.hooks.airflow.providers.ssh.hooks.ssh.SSHHook","filename":"ssh.py","lineno":500}
{"timestamp":"2026-04-25T05:46:04.042917Z","level":"warning","event":"26/04/25 14:46:04 INFO BlockManagerInfo: Added broadcast_0_piece0 in memory on s1:40843 (size: 38.1 KiB, free: 912.3 MiB)","logger":"airflow.task.hooks.airflow.providers.ssh.hooks.ssh.SSHHook","filename":"ssh.py","lineno":500}
{"timestamp":"2026-04-25T05:46:04.134026Z","level":"warning","event":"26/04/25 14:46:04 INFO BlockManagerInfo: Added broadcast_0_piece0 in memory on m2:38991 (size: 38.1 KiB, free: 912.3 MiB)","logger":"airflow.task.hooks.airflow.providers.ssh.hooks.ssh.SSHHook","filename":"ssh.py","lineno":500}
{"timestamp":"2026-04-25T05:46:06.884459Z","level":"warning","event":"26/04/25 14:46:06 INFO TaskSetManager: Starting task 2.0 in stage 0.0 (TID 2) (s1, executor 1, partition 2, NODE_LOCAL, 7437 bytes) ","logger":"airflow.task.hooks.airflow.providers.ssh.hooks.ssh.SSHHook","filename":"ssh.py","lineno":500}
{"timestamp":"2026-04-25T05:46:06.906644Z","level":"warning","event":"26/04/25 14:46:06 INFO TaskSetManager: Finished task 0.0 in stage 0.0 (TID 0) in 4133 ms on s1 (executor 1) (1/892)","logger":"airflow.task.hooks.airflow.providers.ssh.hooks.ssh.SSHHook","filename":"ssh.py","lineno":500}
{"timestamp":"2026-04-25T05:46:06.962085Z","level":"warning","event":"26/04/25 14:46:06 INFO TaskSetManager: Starting task 3.0 in stage 0.0 (TID 3) (s1, executor 1, partition 3, NODE_LOCAL, 7437 bytes) ","logger":"airflow.task.hooks.airflow.providers.ssh.hooks.ssh.SSHHook","filename":"ssh.py","lineno":500}
{"timestamp":"2026-04-25T05:46:06.963222Z","level":"warning","event":"26/04/25 14:46:06 INFO TaskSetManager: Finished task 2.0 in stage 0.0 (TID 2) in 94 ms on s1 (executor 1) (2/892)","logger":"airflow.task.hooks.airflow.providers.ssh.hooks.ssh.SSHHook","filename":"ssh.py","lineno":500}
{"timestamp":"2026-04-25T05:46:07.511022Z","level":"warning","event":"26/04/25 14:46:07 INFO TaskSetManager: Starting task 4.0 in stage 0.0 (TID 4) (m2, executor 2, partition 4, NODE_LOCAL, 7437 bytes) ","logger":"airflow.task.hooks.airflow.providers.ssh.hooks.ssh.SSHHook","filename":"ssh.py","lineno":500}
{"timestamp":"2026-04-25T05:46:07.511265Z","level":"warning","event":"26/04/25 14:46:07 INFO TaskSetManager: Finished task 1.0 in stage 0.0 (TID 1) in 4708 ms on m2 (executor 2) (3/892)","logger":"airflow.task.hooks.airflow.providers.ssh.hooks.ssh.SSHHook","filename":"ssh.py","lineno":500}
{"timestamp":"2026-04-25T05:46:09.269864Z","level":"warning","event":"26/04/25 14:46:09 INFO TaskSetManager: Starting task 5.0 in stage 0.0 (TID 5) (s1, executor 1, partition 5, NODE_LOCAL, 7437 bytes) ","logger":"airflow.task.hooks.airflow.providers.ssh.hooks.ssh.SSHHook","filename":"ssh.py","lineno":500}
{"timestamp":"2026-04-25T05:46:09.271745Z","level":"warning","event":"26/04/25 14:46:09 INFO TaskSetManager: Finished task 3.0 in stage 0.0 (TID 3) in 2311 ms on s1 (executor 1) (4/892)","logger":"airflow.task.hooks.airflow.providers.ssh.hooks.ssh.SSHHook","filename":"ssh.py","lineno":500}
{"timestamp":"2026-04-25T05:46:10.081651Z","level":"warning","event":"26/04/25 14:46:10 INFO TaskSetManager: Starting task 6.0 in stage 0.0 (TID 6) (m2, executor 2, partition 6, NODE_LOCAL, 7437 bytes) ","logger":"airflow.task.hooks.airflow.providers.ssh.hooks.ssh.SSHHook","filename":"ssh.py","lineno":500}
{"timestamp":"2026-04-25T05:46:10.081946Z","level":"warning","event":"26/04/25 14:46:10 INFO TaskSetManager: Finished task 4.0 in stage 0.0 (TID 4) in 2572 ms on m2 (executor 2) (5/892)","logger":"airflow.task.hooks.airflow.providers.ssh.hooks.ssh.SSHHook","filename":"ssh.py","lineno":500}
{"timestamp":"2026-04-25T05:46:10.135983Z","level":"warning","event":"26/04/25 14:46:10 INFO TaskSetManager: Starting task 7.0 in stage 0.0 (TID 7) (m2, executor 2, partition 7, NODE_LOCAL, 7437 bytes) ","logger":"airflow.task.hooks.airflow.providers.ssh.hooks.ssh.SSHHook","filename":"ssh.py","lineno":500}
{"timestamp":"2026-04-25T05:46:10.136421Z","level":"warning","event":"26/04/25 14:46:10 INFO TaskSetManager: Finished task 6.0 in stage 0.0 (TID 6) in 57 ms on m2 (executor 2) (6/892)","logger":"airflow.task.hooks.airflow.providers.ssh.hooks.ssh.SSHHook","filename":"ssh.py","lineno":500}
{"timestamp":"2026-04-25T05:46:10.267381Z","level":"warning","event":"26/04/25 14:46:10 INFO TaskSetManager: Starting task 8.0 in stage 0.0 (TID 8) (m2, executor 2, partition 8, NODE_LOCAL, 7437 bytes) ","logger":"airflow.task.hooks.airflow.providers.ssh.hooks.ssh.SSHHook","filename":"ssh.py","lineno":500}
{"timestamp":"2026-04-25T05:46:10.267717Z","level":"warning","event":"26/04/25 14:46:10 INFO TaskSetManager: Finished task 7.0 in stage 0.0 (TID 7) in 135 ms on m2 (executor 2) (7/892)","logger":"airflow.task.hooks.airflow.providers.ssh.hooks.ssh.SSHHook","filename":"ssh.py","lineno":500}
{"timestamp":"2026-04-25T05:46:10.352735Z","level":"warning","event":"26/04/25 14:46:10 INFO TaskSetManager: Starting task 9.0 in stage 0.0 (TID 9) (m2, executor 2, partition 9, NODE_LOCAL, 7437 bytes) ","logger":"airflow.task.hooks.airflow.providers.ssh.hooks.ssh.SSHHook","filename":"ssh.py","lineno":500}
{"timestamp":"2026-04-25T05:46:10.357179Z","level":"warning","event":"26/04/25 14:46:10 INFO TaskSetManager: Finished task 8.0 in stage 0.0 (TID 8) in 90 ms on m2 (executor 2) (8/892)","logger":"airflow.task.hooks.airflow.providers.ssh.hooks.ssh.SSHHook","filename":"ssh.py","lineno":500}
{"timestamp":"2026-04-25T05:46:10.397800Z","level":"warning","event":"26/04/25 14:46:10 INFO TaskSetManager: Starting task 10.0 in stage 0.0 (TID 10) (m2, executor 2, partition 10, NODE_LOCAL, 7437 bytes) ","logger":"airflow.task.hooks.airflow.providers.ssh.hooks.ssh.SSHHook","filename":"ssh.py","lineno":500}
{"timestamp":"2026-04-25T05:46:10.400238Z","level":"warning","event":"26/04/25 14:46:10 INFO TaskSetManager: Finished task 9.0 in stage 0.0 (TID 9) in 49 ms on m2 (executor 2) (9/892)","logger":"airflow.task.hooks.airflow.providers.ssh.hooks.ssh.SSHHook","filename":"ssh.py","lineno":500}
{"timestamp":"2026-04-25T05:46:10.498682Z","level":"warning","event":"26/04/25 14:46:10 INFO TaskSetManager: Starting task 11.0 in stage 0.0 (TID 11) (m2, executor 2, partition 11, NODE_LOCAL, 7437 bytes) ","logger":"airflow.task.hooks.airflow.providers.ssh.hooks.ssh.SSHHook","filename":"ssh.py","lineno":500}
{"timestamp":"2026-04-25T05:46:10.500001Z","level":"warning","event":"26/04/25 14:46:10 INFO TaskSetManager: Finished task 10.0 in stage 0.0 (TID 10) in 103 ms on m2 (executor 2) (10/892)","logger":"airflow.task.hooks.airflow.providers.ssh.hooks.ssh.SSHHook","filename":"ssh.py","lineno":500}
{"timestamp":"2026-04-25T05:46:10.562792Z","level":"warning","event":"26/04/25 14:46:10 INFO TaskSetManager: Starting task 12.0 in stage 0.0 (TID 12) (m2, executor 2, partition 12, NODE_LOCAL, 7437 bytes) ","logger":"airflow.task.hooks.airflow.providers.ssh.hooks.ssh.SSHHook","filename":"ssh.py","lineno":500}
{"timestamp":"2026-04-25T05:46:10.564537Z","level":"warning","event":"26/04/25 14:46:10 INFO TaskSetManager: Finished task 11.0 in stage 0.0 (TID 11) in 67 ms on m2 (executor 2) (11/892)","logger":"airflow.task.hooks.airflow.providers.ssh.hooks.ssh.SSHHook","filename":"ssh.py","lineno":500}
{"timestamp":"2026-04-25T05:46:10.670181Z","level":"warning","event":"26/04/25 14:46:10 INFO TaskSetManager: Starting task 13.0 in stage 0.0 (TID 13) (m2, executor 2, partition 13, NODE_LOCAL, 7437 bytes) ","logger":"airflow.task.hooks.airflow.providers.ssh.hooks.ssh.SSHHook","filename":"ssh.py","lineno":500}
{"timestamp":"2026-04-25T05:46:10.672647Z","level":"warning","event":"26/04/25 14:46:10 INFO TaskSetManager: Finished task 12.0 in stage 0.0 (TID 12) in 111 ms on m2 (executor 2) (12/892)","logger":"airflow.task.hooks.airflow.providers.ssh.hooks.ssh.SSHHook","filename":"ssh.py","lineno":500}
{"timestamp":"2026-04-25T05:46:10.712294Z","level":"warning","event":"26/04/25 14:46:10 INFO TaskSetManager: Starting task 14.0 in stage 0.0 (TID 14) (m2, executor 2, partition 14, NODE_LOCAL, 7437 bytes) ","logger":"airflow.task.hooks.airflow.providers.ssh.hooks.ssh.SSHHook","filename":"ssh.py","lineno":500}
{"timestamp":"2026-04-25T05:46:10.712562Z","level":"warning","event":"26/04/25 14:46:10 INFO TaskSetManager: Finished task 13.0 in stage 0.0 (TID 13) in 48 ms on m2 (executor 2) (13/892)","logger":"airflow.task.hooks.airflow.providers.ssh.hooks.ssh.SSHHook","filename":"ssh.py","lineno":500}
{"timestamp":"2026-04-25T05:46:10.744976Z","level":"warning","event":"26/04/25 14:46:10 INFO TaskSetManager: Starting task 15.0 in stage 0.0 (TID 15) (m2, executor 2, partition 15, NODE_LOCAL, 7437 bytes) ","logger":"airflow.task.hooks.airflow.providers.ssh.hooks.ssh.SSHHook","filename":"ssh.py","lineno":500}
{"timestamp":"2026-04-25T05:46:10.747694Z","level":"warning","event":"26/04/25 14:46:10 INFO TaskSetManager: Finished task 14.0 in stage 0.0 (TID 14) in 37 ms on m2 (executor 2) (14/892)","logger":"airflow.task.hooks.airflow.providers.ssh.hooks.ssh.SSHHook","filename":"ssh.py","lineno":500}
{"timestamp":"2026-04-25T05:46:10.785719Z","level":"warning","event":"26/04/25 14:46:10 INFO TaskSetManager: Starting task 16.0 in stage 0.0 (TID 16) (m2, executor 2, partition 16, NODE_LOCAL, 7437 bytes) ","logger":"airflow.task.hooks.airflow.providers.ssh.hooks.ssh.SSHHook","filename":"ssh.py","lineno":500}
{"timestamp":"2026-04-25T05:46:10.788968Z","level":"warning","event":"26/04/25 14:46:10 INFO TaskSetManager: Finished task 15.0 in stage 0.0 (TID 15) in 45 ms on m2 (executor 2) (15/892)","logger":"airflow.task.hooks.airflow.providers.ssh.hooks.ssh.SSHHook","filename":"ssh.py","lineno":500}
{"timestamp":"2026-04-25T05:46:10.841905Z","level":"warning","event":"26/04/25 14:46:10 INFO TaskSetManager: Starting task 17.0 in stage 0.0 (TID 17) (m2, executor 2, partition 17, NODE_LOCAL, 7437 bytes) ","logger":"airflow.task.hooks.airflow.providers.ssh.hooks.ssh.SSHHook","filename":"ssh.py","lineno":500}
{"timestamp":"2026-04-25T05:46:10.846091Z","level":"warning","event":"26/04/25 14:46:10 INFO TaskSetManager: Finished task 16.0 in stage 0.0 (TID 16) in 59 ms on m2 (executor 2) (16/892)","logger":"airflow.task.hooks.airflow.providers.ssh.hooks.ssh.SSHHook","filename":"ssh.py","lineno":500}
{"timestamp":"2026-04-25T05:46:10.868865Z","level":"warning","event":"26/04/25 14:46:10 INFO TaskSetManager: Starting task 18.0 in stage 0.0 (TID 18) (s1, executor 1, partition 18, NODE_LOCAL, 7437 bytes) ","logger":"airflow.task.hooks.airflow.providers.ssh.hooks.ssh.SSHHook","filename":"ssh.py","lineno":500}
{"timestamp":"2026-04-25T05:46:10.869118Z","level":"warning","event":"26/04/25 14:46:10 INFO TaskSetManager: Finished task 5.0 in stage 0.0 (TID 5) in 1600 ms on s1 (executor 1) (17/892)","logger":"airflow.task.hooks.airflow.providers.ssh.hooks.ssh.SSHHook","filename":"ssh.py","lineno":500}
{"timestamp":"2026-04-25T05:46:10.883332Z","level":"warning","event":"26/04/25 14:46:10 INFO TaskSetManager: Starting task 19.0 in stage 0.0 (TID 19) (m2, executor 2, partition 19, NODE_LOCAL, 7437 bytes) ","logger":"airflow.task.hooks.airflow.providers.ssh.hooks.ssh.SSHHook","filename":"ssh.py","lineno":500}
{"timestamp":"2026-04-25T05:46:10.884578Z","level":"warning","event":"26/04/25 14:46:10 INFO TaskSetManager: Finished task 17.0 in stage 0.0 (TID 17) in 43 ms on m2 (executor 2) (18/892)","logger":"airflow.task.hooks.airflow.providers.ssh.hooks.ssh.SSHHook","filename":"ssh.py","lineno":500}
{"timestamp":"2026-04-25T05:46:11.043758Z","level":"warning","event":"26/04/25 14:46:11 INFO TaskSetManager: Starting task 20.0 in stage 0.0 (TID 20) (s1, executor 1, partition 20, NODE_LOCAL, 7437 bytes) ","logger":"airflow.task.hooks.airflow.providers.ssh.hooks.ssh.SSHHook","filename":"ssh.py","lineno":500}
{"timestamp":"2026-04-25T05:46:11.044861Z","level":"warning","event":"26/04/25 14:46:11 INFO TaskSetManager: Finished task 18.0 in stage 0.0 (TID 18) in 178 ms on s1 (executor 1) (19/892)","logger":"airflow.task.hooks.airflow.providers.ssh.hooks.ssh.SSHHook","filename":"ssh.py","lineno":500}
{"timestamp":"2026-04-25T05:46:11.101700Z","level":"warning","event":"26/04/25 14:46:11 INFO TaskSetManager: Starting task 21.0 in stage 0.0 (TID 21) (m2, executor 2, partition 21, NODE_LOCAL, 7437 bytes) ","logger":"airflow.task.hooks.airflow.providers.ssh.hooks.ssh.SSHHook","filename":"ssh.py","lineno":500}
{"timestamp":"2026-04-25T05:46:11.102784Z","level":"warning","event":"26/04/25 14:46:11 INFO TaskSetManager: Finished task 19.0 in stage 0.0 (TID 19) in 222 ms on m2 (executor 2) (20/892)","logger":"airflow.task.hooks.airflow.providers.ssh.hooks.ssh.SSHHook","filename":"ssh.py","lineno":500}
{"timestamp":"2026-04-25T05:46:11.142062Z","level":"warning","event":"26/04/25 14:46:11 INFO TaskSetManager: Starting task 22.0 in stage 0.0 (TID 22) (m2, executor 2, partition 22, NODE_LOCAL, 7437 bytes) ","logger":"airflow.task.hooks.airflow.providers.ssh.hooks.ssh.SSHHook","filename":"ssh.py","lineno":500}
{"timestamp":"2026-04-25T05:46:11.143396Z","level":"warning","event":"26/04/25 14:46:11 INFO TaskSetManager: Finished task 21.0 in stage 0.0 (TID 21) in 43 ms on m2 (executor 2) (21/892)","logger":"airflow.task.hooks.airflow.providers.ssh.hooks.ssh.SSHHook","filename":"ssh.py","lineno":500}
{"timestamp":"2026-04-25T05:46:11.170507Z","level":"warning","event":"26/04/25 14:46:11 INFO TaskSetManager: Starting task 23.0 in stage 0.0 (TID 23) (m2, executor 2, partition 23, NODE_LOCAL, 7437 bytes) ","logger":"airflow.task.hooks.airflow.providers.ssh.hooks.ssh.SSHHook","filename":"ssh.py","lineno":500}
{"timestamp":"2026-04-25T05:46:11.171562Z","level":"warning","event":"26/04/25 14:46:11 INFO TaskSetManager: Finished task 22.0 in stage 0.0 (TID 22) in 30 ms on m2 (executor 2) (22/892)","logger":"airflow.task.hooks.airflow.providers.ssh.hooks.ssh.SSHHook","filename":"ssh.py","lineno":500}
{"timestamp":"2026-04-25T05:46:11.199505Z","level":"warning","event":"26/04/25 14:46:11 INFO TaskSetManager: Starting task 24.0 in stage 0.0 (TID 24) (m2, executor 2, partition 24, NODE_LOCAL, 7437 bytes) ","logger":"airflow.task.hooks.airflow.providers.ssh.hooks.ssh.SSHHook","filename":"ssh.py","lineno":500}
{"timestamp":"2026-04-25T05:46:11.199741Z","level":"warning","event":"26/04/25 14:46:11 INFO TaskSetManager: Finished task 23.0 in stage 0.0 (TID 23) in 31 ms on m2 (executor 2) (23/892)","logger":"airflow.task.hooks.airflow.providers.ssh.hooks.ssh.SSHHook","filename":"ssh.py","lineno":500}
{"timestamp":"2026-04-25T05:46:11.226435Z","level":"warning","event":"26/04/25 14:46:11 INFO TaskSetManager: Starting task 25.0 in stage 0.0 (TID 25) (s1, executor 1, partition 25, NODE_LOCAL, 7437 bytes) ","logger":"airflow.task.hooks.airflow.providers.ssh.hooks.ssh.SSHHook","filename":"ssh.py","lineno":500}
{"timestamp":"2026-04-25T05:46:11.226785Z","level":"warning","event":"26/04/25 14:46:11 INFO TaskSetManager: Finished task 20.0 in stage 0.0 (TID 20) in 183 ms on s1 (executor 1) (24/892)","logger":"airflow.task.hooks.airflow.providers.ssh.hooks.ssh.SSHHook","filename":"ssh.py","lineno":500}
{"timestamp":"2026-04-25T05:46:11.230268Z","level":"warning","event":"26/04/25 14:46:11 INFO TaskSetManager: Starting task 26.0 in stage 0.0 (TID 26) (m2, executor 2, partition 26, NODE_LOCAL, 7437 bytes) ","logger":"airflow.task.hooks.airflow.providers.ssh.hooks.ssh.SSHHook","filename":"ssh.py","lineno":500}
{"timestamp":"2026-04-25T05:46:11.230506Z","level":"warning","event":"26/04/25 14:46:11 INFO TaskSetManager: Finished task 24.0 in stage 0.0 (TID 24) in 32 ms on m2 (executor 2) (25/892)","logger":"airflow.task.hooks.airflow.providers.ssh.hooks.ssh.SSHHook","filename":"ssh.py","lineno":500}
{"timestamp":"2026-04-25T05:46:11.266897Z","level":"warning","event":"26/04/25 14:46:11 INFO TaskSetManager: Starting task 27.0 in stage 0.0 (TID 27) (m2, executor 2, partition 27, NODE_LOCAL, 7437 bytes) ","logger":"airflow.task.hooks.airflow.providers.ssh.hooks.ssh.SSHHook","filename":"ssh.py","lineno":500}
{"timestamp":"2026-04-25T05:46:11.267305Z","level":"warning","event":"26/04/25 14:46:11 INFO TaskSetManager: Starting task 28.0 in stage 0.0 (TID 28) (s1, executor 1, partition 28, NODE_LOCAL, 7437 bytes) ","logger":"airflow.task.hooks.airflow.providers.ssh.hooks.ssh.SSHHook","filename":"ssh.py","lineno":500}
{"timestamp":"2026-04-25T05:46:11.273626Z","level":"warning","event":"26/04/25 14:46:11 INFO TaskSetManager: Finished task 25.0 in stage 0.0 (TID 25) in 48 ms on s1 (executor 1) (26/892)","logger":"airflow.task.hooks.airflow.providers.ssh.hooks.ssh.SSHHook","filename":"ssh.py","lineno":500}
{"timestamp":"2026-04-25T05:46:11.275303Z","level":"warning","event":"26/04/25 14:46:11 INFO TaskSetManager: Finished task 26.0 in stage 0.0 (TID 26) in 42 ms on m2 (executor 2) (27/892)","logger":"airflow.task.hooks.airflow.providers.ssh.hooks.ssh.SSHHook","filename":"ssh.py","lineno":500}
{"timestamp":"2026-04-25T05:46:11.294898Z","level":"warning","event":"26/04/25 14:46:11 INFO TaskSetManager: Starting task 29.0 in stage 0.0 (TID 29) (m2, executor 2, partition 29, NODE_LOCAL, 7437 bytes) ","logger":"airflow.task.hooks.airflow.providers.ssh.hooks.ssh.SSHHook","filename":"ssh.py","lineno":500}
{"timestamp":"2026-04-25T05:46:11.295216Z","level":"warning","event":"26/04/25 14:46:11 INFO TaskSetManager: Finished task 27.0 in stage 0.0 (TID 27) in 30 ms on m2 (executor 2) (28/892)","logger":"airflow.task.hooks.airflow.providers.ssh.hooks.ssh.SSHHook","filename":"ssh.py","lineno":500}
{"timestamp":"2026-04-25T05:46:11.310665Z","level":"warning","event":"26/04/25 14:46:11 INFO TaskSetManager: Starting task 30.0 in stage 0.0 (TID 30) (s1, executor 1, partition 30, NODE_LOCAL, 7437 bytes) ","logger":"airflow.task.hooks.airflow.providers.ssh.hooks.ssh.SSHHook","filename":"ssh.py","lineno":500}
{"timestamp":"2026-04-25T05:46:11.311720Z","level":"warning","event":"26/04/25 14:46:11 INFO TaskSetManager: Finished task 28.0 in stage 0.0 (TID 28) in 45 ms on s1 (executor 1) (29/892)","logger":"airflow.task.hooks.airflow.providers.ssh.hooks.ssh.SSHHook","filename":"ssh.py","lineno":500}
{"timestamp":"2026-04-25T05:46:11.320117Z","level":"warning","event":"26/04/25 14:46:11 INFO TaskSetManager: Starting task 31.0 in stage 0.0 (TID 31) (m2, executor 2, partition 31, NODE_LOCAL, 7437 bytes) ","logger":"airflow.task.hooks.airflow.providers.ssh.hooks.ssh.SSHHook","filename":"ssh.py","lineno":500}
{"timestamp":"2026-04-25T05:46:11.321065Z","level":"warning","event":"26/04/25 14:46:11 INFO TaskSetManager: Finished task 29.0 in stage 0.0 (TID 29) in 30 ms on m2 (executor 2) (30/892)","logger":"airflow.task.hooks.airflow.providers.ssh.hooks.ssh.SSHHook","filename":"ssh.py","lineno":500}
{"timestamp":"2026-04-25T05:46:11.354920Z","level":"warning","event":"26/04/25 14:46:11 INFO TaskSetManager: Starting task 32.0 in stage 0.0 (TID 32) (s1, executor 1, partition 32, NODE_LOCAL, 7437 bytes) ","logger":"airflow.task.hooks.airflow.providers.ssh.hooks.ssh.SSHHook","filename":"ssh.py","lineno":500}
{"timestamp":"2026-04-25T05:46:11.358066Z","level":"warning","event":"26/04/25 14:46:11 INFO TaskSetManager: Finished task 30.0 in stage 0.0 (TID 30) in 48 ms on s1 (executor 1) (31/892)","logger":"airflow.task.hooks.airflow.providers.ssh.hooks.ssh.SSHHook","filename":"ssh.py","lineno":500}
{"timestamp":"2026-04-25T05:46:11.360060Z","level":"warning","event":"26/04/25 14:46:11 INFO TaskSetManager: Starting task 33.0 in stage 0.0 (TID 33) (m2, executor 2, partition 33, NODE_LOCAL, 7437 bytes) ","logger":"airflow.task.hooks.airflow.providers.ssh.hooks.ssh.SSHHook","filename":"ssh.py","lineno":500}
{"timestamp":"2026-04-25T05:46:11.361127Z","level":"warning","event":"26/04/25 14:46:11 INFO TaskSetManager: Finished task 31.0 in stage 0.0 (TID 31) in 43 ms on m2 (executor 2) (32/892)","logger":"airflow.task.hooks.airflow.providers.ssh.hooks.ssh.SSHHook","filename":"ssh.py","lineno":500}
{"timestamp":"2026-04-25T05:46:11.388518Z","level":"warning","event":"26/04/25 14:46:11 INFO TaskSetManager: Starting task 34.0 in stage 0.0 (TID 34) (m2, executor 2, partition 34, NODE_LOCAL, 7437 bytes) ","logger":"airflow.task.hooks.airflow.providers.ssh.hooks.ssh.SSHHook","filename":"ssh.py","lineno":500}
{"timestamp":"2026-04-25T05:46:11.389407Z","level":"warning","event":"26/04/25 14:46:11 INFO TaskSetManager: Finished task 33.0 in stage 0.0 (TID 33) in 30 ms on m2 (executor 2) (33/892)","logger":"airflow.task.hooks.airflow.providers.ssh.hooks.ssh.SSHHook","filename":"ssh.py","lineno":500}
{"timestamp":"2026-04-25T05:46:11.399915Z","level":"warning","event":"26/04/25 14:46:11 INFO TaskSetManager: Starting task 35.0 in stage 0.0 (TID 35) (s1, executor 1, partition 35, NODE_LOCAL, 7437 bytes) ","logger":"airflow.task.hooks.airflow.providers.ssh.hooks.ssh.SSHHook","filename":"ssh.py","lineno":500}
{"timestamp":"2026-04-25T05:46:11.401031Z","level":"warning","event":"26/04/25 14:46:11 INFO TaskSetManager: Finished task 32.0 in stage 0.0 (TID 32) in 47 ms on s1 (executor 1) (34/892)","logger":"airflow.task.hooks.airflow.providers.ssh.hooks.ssh.SSHHook","filename":"ssh.py","lineno":500}
{"timestamp":"2026-04-25T05:46:11.415510Z","level":"warning","event":"26/04/25 14:46:11 INFO TaskSetManager: Starting task 36.0 in stage 0.0 (TID 36) (m2, executor 2, partition 36, NODE_LOCAL, 7437 bytes) ","logger":"airflow.task.hooks.airflow.providers.ssh.hooks.ssh.SSHHook","filename":"ssh.py","lineno":500}
{"timestamp":"2026-04-25T05:46:11.416330Z","level":"warning","event":"26/04/25 14:46:11 INFO TaskSetManager: Finished task 34.0 in stage 0.0 (TID 34) in 28 ms on m2 (executor 2) (35/892)","logger":"airflow.task.hooks.airflow.providers.ssh.hooks.ssh.SSHHook","filename":"ssh.py","lineno":500}
{"timestamp":"2026-04-25T05:46:11.441059Z","level":"warning","event":"26/04/25 14:46:11 INFO TaskSetManager: Starting task 37.0 in stage 0.0 (TID 37) (s1, executor 1, partition 37, NODE_LOCAL, 7437 bytes) ","logger":"airflow.task.hooks.airflow.providers.ssh.hooks.ssh.SSHHook","filename":"ssh.py","lineno":500}
{"timestamp":"2026-04-25T05:46:11.445359Z","level":"warning","event":"26/04/25 14:46:11 INFO TaskSetManager: Finished task 35.0 in stage 0.0 (TID 35) in 46 ms on s1 (executor 1) (36/892)","logger":"airflow.task.hooks.airflow.providers.ssh.hooks.ssh.SSHHook","filename":"ssh.py","lineno":500}
{"timestamp":"2026-04-25T05:46:11.446889Z","level":"warning","event":"26/04/25 14:46:11 INFO TaskSetManager: Starting task 38.0 in stage 0.0 (TID 38) (m2, executor 2, partition 38, NODE_LOCAL, 7437 bytes) ","logger":"airflow.task.hooks.airflow.providers.ssh.hooks.ssh.SSHHook","filename":"ssh.py","lineno":500}
{"timestamp":"2026-04-25T05:46:11.448015Z","level":"warning","event":"26/04/25 14:46:11 INFO TaskSetManager: Finished task 36.0 in stage 0.0 (TID 36) in 33 ms on m2 (executor 2) (37/892)","logger":"airflow.task.hooks.airflow.providers.ssh.hooks.ssh.SSHHook","filename":"ssh.py","lineno":500}
{"timestamp":"2026-04-25T05:46:11.476217Z","level":"warning","event":"26/04/25 14:46:11 INFO TaskSetManager: Starting task 39.0 in stage 0.0 (TID 39) (m2, executor 2, partition 39, NODE_LOCAL, 7437 bytes) ","logger":"airflow.task.hooks.airflow.providers.ssh.hooks.ssh.SSHHook","filename":"ssh.py","lineno":500}
{"timestamp":"2026-04-25T05:46:11.478824Z","level":"warning","event":"26/04/25 14:46:11 INFO TaskSetManager: Finished task 38.0 in stage 0.0 (TID 38) in 31 ms on m2 (executor 2) (38/892)","logger":"airflow.task.hooks.airflow.providers.ssh.hooks.ssh.SSHHook","filename":"ssh.py","lineno":500}
{"timestamp":"2026-04-25T05:46:11.485425Z","level":"warning","event":"26/04/25 14:46:11 INFO TaskSetManager: Finished task 37.0 in stage 0.0 (TID 37) in 45 ms on s1 (executor 1) (39/892)","logger":"airflow.task.hooks.airflow.providers.ssh.hooks.ssh.SSHHook","filename":"ssh.py","lineno":500}
{"timestamp":"2026-04-25T05:46:11.488211Z","level":"warning","event":"26/04/25 14:46:11 INFO TaskSetManager: Starting task 40.0 in stage 0.0 (TID 40) (s1, executor 1, partition 40, NODE_LOCAL, 7437 bytes) ","logger":"airflow.task.hooks.airflow.providers.ssh.hooks.ssh.SSHHook","filename":"ssh.py","lineno":500}
{"timestamp":"2026-04-25T05:46:11.509229Z","level":"warning","event":"26/04/25 14:46:11 INFO TaskSetManager: Finished task 39.0 in stage 0.0 (TID 39) in 34 ms on m2 (executor 2) (40/892)","logger":"airflow.task.hooks.airflow.providers.ssh.hooks.ssh.SSHHook","filename":"ssh.py","lineno":500}
{"timestamp":"2026-04-25T05:46:11.513475Z","level":"warning","event":"26/04/25 14:46:11 INFO TaskSetManager: Starting task 41.0 in stage 0.0 (TID 41) (m2, executor 2, partition 41, NODE_LOCAL, 7437 bytes) ","logger":"airflow.task.hooks.airflow.providers.ssh.hooks.ssh.SSHHook","filename":"ssh.py","lineno":500}
{"timestamp":"2026-04-25T05:46:11.539255Z","level":"warning","event":"26/04/25 14:46:11 INFO TaskSetManager: Starting task 42.0 in stage 0.0 (TID 42) (s1, executor 1, partition 42, NODE_LOCAL, 7437 bytes) ","logger":"airflow.task.hooks.airflow.providers.ssh.hooks.ssh.SSHHook","filename":"ssh.py","lineno":500}
{"timestamp":"2026-04-25T05:46:11.539465Z","level":"warning","event":"26/04/25 14:46:11 INFO TaskSetManager: Finished task 40.0 in stage 0.0 (TID 40) in 48 ms on s1 (executor 1) (41/892)","logger":"airflow.task.hooks.airflow.providers.ssh.hooks.ssh.SSHHook","filename":"ssh.py","lineno":500}
{"timestamp":"2026-04-25T05:46:11.549944Z","level":"warning","event":"26/04/25 14:46:11 INFO TaskSetManager: Starting task 43.0 in stage 0.0 (TID 43) (m2, executor 2, partition 43, NODE_LOCAL, 7437 bytes) ","logger":"airflow.task.hooks.airflow.providers.ssh.hooks.ssh.SSHHook","filename":"ssh.py","lineno":500}
{"timestamp":"2026-04-25T05:46:11.554196Z","level":"warning","event":"26/04/25 14:46:11 INFO TaskSetManager: Finished task 41.0 in stage 0.0 (TID 41) in 42 ms on m2 (executor 2) (42/892)","logger":"airflow.task.hooks.airflow.providers.ssh.hooks.ssh.SSHHook","filename":"ssh.py","lineno":500}
{"timestamp":"2026-04-25T05:46:11.574916Z","level":"warning","event":"26/04/25 14:46:11 INFO TaskSetManager: Finished task 42.0 in stage 0.0 (TID 42) in 47 ms on s1 (executor 1) (43/892)","logger":"airflow.task.hooks.airflow.providers.ssh.hooks.ssh.SSHHook","filename":"ssh.py","lineno":500}
{"timestamp":"2026-04-25T05:46:11.577319Z","level":"warning","event":"26/04/25 14:46:11 INFO TaskSetManager: Starting task 44.0 in stage 0.0 (TID 44) (s1, executor 1, partition 44, NODE_LOCAL, 7437 bytes) ","logger":"airflow.task.hooks.airflow.providers.ssh.hooks.ssh.SSHHook","filename":"ssh.py","lineno":500}
{"timestamp":"2026-04-25T05:46:11.585598Z","level":"warning","event":"26/04/25 14:46:11 INFO TaskSetManager: Finished task 43.0 in stage 0.0 (TID 43) in 36 ms on m2 (executor 2) (44/892)","logger":"airflow.task.hooks.airflow.providers.ssh.hooks.ssh.SSHHook","filename":"ssh.py","lineno":500}
{"timestamp":"2026-04-25T05:46:11.589061Z","level":"warning","event":"26/04/25 14:46:11 INFO TaskSetManager: Starting task 45.0 in stage 0.0 (TID 45) (m2, executor 2, partition 45, NODE_LOCAL, 7437 bytes) ","logger":"airflow.task.hooks.airflow.providers.ssh.hooks.ssh.SSHHook","filename":"ssh.py","lineno":500}
{"timestamp":"2026-04-25T05:46:11.613169Z","level":"warning","event":"26/04/25 14:46:11 INFO TaskSetManager: Starting task 46.0 in stage 0.0 (TID 46) (m2, executor 2, partition 46, NODE_LOCAL, 7437 bytes) ","logger":"airflow.task.hooks.airflow.providers.ssh.hooks.ssh.SSHHook","filename":"ssh.py","lineno":500}
{"timestamp":"2026-04-25T05:46:11.615088Z","level":"warning","event":"26/04/25 14:46:11 INFO TaskSetManager: Finished task 45.0 in stage 0.0 (TID 45) in 28 ms on m2 (executor 2) (45/892)","logger":"airflow.task.hooks.airflow.providers.ssh.hooks.ssh.SSHHook","filename":"ssh.py","lineno":500}
{"timestamp":"2026-04-25T05:46:11.618927Z","level":"warning","event":"26/04/25 14:46:11 INFO TaskSetManager: Starting task 47.0 in stage 0.0 (TID 47) (s1, executor 1, partition 47, NODE_LOCAL, 7437 bytes) ","logger":"airflow.task.hooks.airflow.providers.ssh.hooks.ssh.SSHHook","filename":"ssh.py","lineno":500}
{"timestamp":"2026-04-25T05:46:11.620760Z","level":"warning","event":"26/04/25 14:46:11 INFO TaskSetManager: Finished task 44.0 in stage 0.0 (TID 44) in 43 ms on s1 (executor 1) (46/892)","logger":"airflow.task.hooks.airflow.providers.ssh.hooks.ssh.SSHHook","filename":"ssh.py","lineno":500}
{"timestamp":"2026-04-25T05:46:11.661140Z","level":"warning","event":"26/04/25 14:46:11 INFO TaskSetManager: Starting task 48.0 in stage 0.0 (TID 48) (m2, executor 2, partition 48, NODE_LOCAL, 7437 bytes) ","logger":"airflow.task.hooks.airflow.providers.ssh.hooks.ssh.SSHHook","filename":"ssh.py","lineno":500}
{"timestamp":"2026-04-25T05:46:11.662254Z","level":"warning","event":"26/04/25 14:46:11 INFO TaskSetManager: Finished task 46.0 in stage 0.0 (TID 46) in 50 ms on m2 (executor 2) (47/892)","logger":"airflow.task.hooks.airflow.providers.ssh.hooks.ssh.SSHHook","filename":"ssh.py","lineno":500}
{"timestamp":"2026-04-25T05:46:11.669898Z","level":"warning","event":"26/04/25 14:46:11 INFO TaskSetManager: Starting task 49.0 in stage 0.0 (TID 49) (s1, executor 1, partition 49, NODE_LOCAL, 7437 bytes) ","logger":"airflow.task.hooks.airflow.providers.ssh.hooks.ssh.SSHHook","filename":"ssh.py","lineno":500}
{"timestamp":"2026-04-25T05:46:11.672528Z","level":"warning","event":"26/04/25 14:46:11 INFO TaskSetManager: Finished task 47.0 in stage 0.0 (TID 47) in 54 ms on s1 (executor 1) (48/892)","logger":"airflow.task.hooks.airflow.providers.ssh.hooks.ssh.SSHHook","filename":"ssh.py","lineno":500}
{"timestamp":"2026-04-25T05:46:11.703208Z","level":"warning","event":"26/04/25 14:46:11 INFO TaskSetManager: Starting task 50.0 in stage 0.0 (TID 50) (m2, executor 2, partition 50, NODE_LOCAL, 7437 bytes) ","logger":"airflow.task.hooks.airflow.providers.ssh.hooks.ssh.SSHHook","filename":"ssh.py","lineno":500}
{"timestamp":"2026-04-25T05:46:11.704314Z","level":"warning","event":"26/04/25 14:46:11 INFO TaskSetManager: Finished task 48.0 in stage 0.0 (TID 48) in 44 ms on m2 (executor 2) (49/892)","logger":"airflow.task.hooks.airflow.providers.ssh.hooks.ssh.SSHHook","filename":"ssh.py","lineno":500}
{"timestamp":"2026-04-25T05:46:11.707088Z","level":"warning","event":"26/04/25 14:46:11 INFO TaskSetManager: Starting task 51.0 in stage 0.0 (TID 51) (s1, executor 1, partition 51, NODE_LOCAL, 7437 bytes) ","logger":"airflow.task.hooks.airflow.providers.ssh.hooks.ssh.SSHHook","filename":"ssh.py","lineno":500}
{"timestamp":"2026-04-25T05:46:11.707925Z","level":"warning","event":"26/04/25 14:46:11 INFO TaskSetManager: Finished task 49.0 in stage 0.0 (TID 49) in 42 ms on s1 (executor 1) (50/892)","logger":"airflow.task.hooks.airflow.providers.ssh.hooks.ssh.SSHHook","filename":"ssh.py","lineno":500}
{"timestamp":"2026-04-25T05:46:11.738222Z","level":"warning","event":"26/04/25 14:46:11 INFO TaskSetManager: Finished task 50.0 in stage 0.0 (TID 50) in 36 ms on m2 (executor 2) (51/892)","logger":"airflow.task.hooks.airflow.providers.ssh.hooks.ssh.SSHHook","filename":"ssh.py","lineno":500}
{"timestamp":"2026-04-25T05:46:11.739909Z","level":"warning","event":"26/04/25 14:46:11 INFO TaskSetManager: Starting task 52.0 in stage 0.0 (TID 52) (m2, executor 2, partition 52, NODE_LOCAL, 7437 bytes) ","logger":"airflow.task.hooks.airflow.providers.ssh.hooks.ssh.SSHHook","filename":"ssh.py","lineno":500}
{"timestamp":"2026-04-25T05:46:11.752075Z","level":"warning","event":"26/04/25 14:46:11 INFO TaskSetManager: Starting task 53.0 in stage 0.0 (TID 53) (s1, executor 1, partition 53, NODE_LOCAL, 7437 bytes) ","logger":"airflow.task.hooks.airflow.providers.ssh.hooks.ssh.SSHHook","filename":"ssh.py","lineno":500}
{"timestamp":"2026-04-25T05:46:11.753219Z","level":"warning","event":"26/04/25 14:46:11 INFO TaskSetManager: Finished task 51.0 in stage 0.0 (TID 51) in 47 ms on s1 (executor 1) (52/892)","logger":"airflow.task.hooks.airflow.providers.ssh.hooks.ssh.SSHHook","filename":"ssh.py","lineno":500}
{"timestamp":"2026-04-25T05:46:11.780971Z","level":"warning","event":"26/04/25 14:46:11 INFO TaskSetManager: Starting task 54.0 in stage 0.0 (TID 54) (m2, executor 2, partition 54, NODE_LOCAL, 7437 bytes) ","logger":"airflow.task.hooks.airflow.providers.ssh.hooks.ssh.SSHHook","filename":"ssh.py","lineno":500}
{"timestamp":"2026-04-25T05:46:11.782027Z","level":"warning","event":"26/04/25 14:46:11 INFO TaskSetManager: Finished task 52.0 in stage 0.0 (TID 52) in 43 ms on m2 (executor 2) (53/892)","logger":"airflow.task.hooks.airflow.providers.ssh.hooks.ssh.SSHHook","filename":"ssh.py","lineno":500}
{"timestamp":"2026-04-25T05:46:11.785578Z","level":"warning","event":"26/04/25 14:46:11 INFO TaskSetManager: Starting task 55.0 in stage 0.0 (TID 55) (s1, executor 1, partition 55, NODE_LOCAL, 7437 bytes) ","logger":"airflow.task.hooks.airflow.providers.ssh.hooks.ssh.SSHHook","filename":"ssh.py","lineno":500}
{"timestamp":"2026-04-25T05:46:11.786668Z","level":"warning","event":"26/04/25 14:46:11 INFO TaskSetManager: Finished task 53.0 in stage 0.0 (TID 53) in 35 ms on s1 (executor 1) (54/892)","logger":"airflow.task.hooks.airflow.providers.ssh.hooks.ssh.SSHHook","filename":"ssh.py","lineno":500}
{"timestamp":"2026-04-25T05:46:11.821975Z","level":"warning","event":"26/04/25 14:46:11 INFO TaskSetManager: Starting task 56.0 in stage 0.0 (TID 56) (s1, executor 1, partition 56, NODE_LOCAL, 7437 bytes) ","logger":"airflow.task.hooks.airflow.providers.ssh.hooks.ssh.SSHHook","filename":"ssh.py","lineno":500}
{"timestamp":"2026-04-25T05:46:11.826514Z","level":"warning","event":"26/04/25 14:46:11 INFO TaskSetManager: Finished task 55.0 in stage 0.0 (TID 55) in 40 ms on s1 (executor 1) (55/892)","logger":"airflow.task.hooks.airflow.providers.ssh.hooks.ssh.SSHHook","filename":"ssh.py","lineno":500}
{"timestamp":"2026-04-25T05:46:11.831709Z","level":"warning","event":"26/04/25 14:46:11 INFO TaskSetManager: Finished task 54.0 in stage 0.0 (TID 54) in 51 ms on m2 (executor 2) (56/892)","logger":"airflow.task.hooks.airflow.providers.ssh.hooks.ssh.SSHHook","filename":"ssh.py","lineno":500}
{"timestamp":"2026-04-25T05:46:11.833602Z","level":"warning","event":"26/04/25 14:46:11 INFO TaskSetManager: Starting task 57.0 in stage 0.0 (TID 57) (m2, executor 2, partition 57, NODE_LOCAL, 7437 bytes) ","logger":"airflow.task.hooks.airflow.providers.ssh.hooks.ssh.SSHHook","filename":"ssh.py","lineno":500}
{"timestamp":"2026-04-25T05:46:11.865874Z","level":"warning","event":"26/04/25 14:46:11 INFO TaskSetManager: Starting task 58.0 in stage 0.0 (TID 58) (s1, executor 1, partition 58, NODE_LOCAL, 7437 bytes) ","logger":"airflow.task.hooks.airflow.providers.ssh.hooks.ssh.SSHHook","filename":"ssh.py","lineno":500}
{"timestamp":"2026-04-25T05:46:11.868755Z","level":"warning","event":"26/04/25 14:46:11 INFO TaskSetManager: Finished task 56.0 in stage 0.0 (TID 56) in 51 ms on s1 (executor 1) (57/892)","logger":"airflow.task.hooks.airflow.providers.ssh.hooks.ssh.SSHHook","filename":"ssh.py","lineno":500}
{"timestamp":"2026-04-25T05:46:11.870501Z","level":"warning","event":"26/04/25 14:46:11 INFO TaskSetManager: Starting task 59.0 in stage 0.0 (TID 59) (m2, executor 2, partition 59, NODE_LOCAL, 7437 bytes) ","logger":"airflow.task.hooks.airflow.providers.ssh.hooks.ssh.SSHHook","filename":"ssh.py","lineno":500}
{"timestamp":"2026-04-25T05:46:11.876151Z","level":"warning","event":"26/04/25 14:46:11 INFO TaskSetManager: Finished task 57.0 in stage 0.0 (TID 57) in 43 ms on m2 (executor 2) (58/892)","logger":"airflow.task.hooks.airflow.providers.ssh.hooks.ssh.SSHHook","filename":"ssh.py","lineno":500}
{"timestamp":"2026-04-25T05:46:11.898965Z","level":"warning","event":"26/04/25 14:46:11 INFO TaskSetManager: Finished task 58.0 in stage 0.0 (TID 58) in 37 ms on s1 (executor 1) (59/892)","logger":"airflow.task.hooks.airflow.providers.ssh.hooks.ssh.SSHHook","filename":"ssh.py","lineno":500}
{"timestamp":"2026-04-25T05:46:11.902937Z","level":"warning","event":"26/04/25 14:46:11 INFO TaskSetManager: Starting task 60.0 in stage 0.0 (TID 60) (s1, executor 1, partition 60, NODE_LOCAL, 7437 bytes) ","logger":"airflow.task.hooks.airflow.providers.ssh.hooks.ssh.SSHHook","filename":"ssh.py","lineno":500}
{"timestamp":"2026-04-25T05:46:11.904506Z","level":"warning","event":"26/04/25 14:46:11 INFO TaskSetManager: Starting task 61.0 in stage 0.0 (TID 61) (m2, executor 2, partition 61, NODE_LOCAL, 7437 bytes) ","logger":"airflow.task.hooks.airflow.providers.ssh.hooks.ssh.SSHHook","filename":"ssh.py","lineno":500}
{"timestamp":"2026-04-25T05:46:11.905390Z","level":"warning","event":"26/04/25 14:46:11 INFO TaskSetManager: Finished task 59.0 in stage 0.0 (TID 59) in 35 ms on m2 (executor 2) (60/892)","logger":"airflow.task.hooks.airflow.providers.ssh.hooks.ssh.SSHHook","filename":"ssh.py","lineno":500}
{"timestamp":"2026-04-25T05:46:11.937298Z","level":"warning","event":"26/04/25 14:46:11 INFO TaskSetManager: Starting task 62.0 in stage 0.0 (TID 62) (s1, executor 1, partition 62, NODE_LOCAL, 7437 bytes) ","logger":"airflow.task.hooks.airflow.providers.ssh.hooks.ssh.SSHHook","filename":"ssh.py","lineno":500}
{"timestamp":"2026-04-25T05:46:11.938411Z","level":"warning","event":"26/04/25 14:46:11 INFO TaskSetManager: Finished task 60.0 in stage 0.0 (TID 60) in 36 ms on s1 (executor 1) (61/892)","logger":"airflow.task.hooks.airflow.providers.ssh.hooks.ssh.SSHHook","filename":"ssh.py","lineno":500}
{"timestamp":"2026-04-25T05:46:11.941069Z","level":"warning","event":"26/04/25 14:46:11 INFO TaskSetManager: Starting task 63.0 in stage 0.0 (TID 63) (m2, executor 2, partition 63, NODE_LOCAL, 7437 bytes) ","logger":"airflow.task.hooks.airflow.providers.ssh.hooks.ssh.SSHHook","filename":"ssh.py","lineno":500}
{"timestamp":"2026-04-25T05:46:11.942132Z","level":"warning","event":"26/04/25 14:46:11 INFO TaskSetManager: Finished task 61.0 in stage 0.0 (TID 61) in 38 ms on m2 (executor 2) (62/892)","logger":"airflow.task.hooks.airflow.providers.ssh.hooks.ssh.SSHHook","filename":"ssh.py","lineno":500}
{"timestamp":"2026-04-25T05:46:11.974389Z","level":"warning","event":"26/04/25 14:46:11 INFO TaskSetManager: Finished task 63.0 in stage 0.0 (TID 63) in 28 ms on m2 (executor 2) (63/892)","logger":"airflow.task.hooks.airflow.providers.ssh.hooks.ssh.SSHHook","filename":"ssh.py","lineno":500}
{"timestamp":"2026-04-25T05:46:11.976716Z","level":"warning","event":"26/04/25 14:46:11 INFO TaskSetManager: Starting task 64.0 in stage 0.0 (TID 64) (m2, executor 2, partition 64, NODE_LOCAL, 7437 bytes) ","logger":"airflow.task.hooks.airflow.providers.ssh.hooks.ssh.SSHHook","filename":"ssh.py","lineno":500}
{"timestamp":"2026-04-25T05:46:11.978664Z","level":"warning","event":"26/04/25 14:46:11 INFO TaskSetManager: Starting task 65.0 in stage 0.0 (TID 65) (s1, executor 1, partition 65, NODE_LOCAL, 7437 bytes) ","logger":"airflow.task.hooks.airflow.providers.ssh.hooks.ssh.SSHHook","filename":"ssh.py","lineno":500}
{"timestamp":"2026-04-25T05:46:11.982713Z","level":"warning","event":"26/04/25 14:46:11 INFO TaskSetManager: Finished task 62.0 in stage 0.0 (TID 62) in 45 ms on s1 (executor 1) (64/892)","logger":"airflow.task.hooks.airflow.providers.ssh.hooks.ssh.SSHHook","filename":"ssh.py","lineno":500}
{"timestamp":"2026-04-25T05:46:12.002490Z","level":"warning","event":"26/04/25 14:46:12 INFO TaskSetManager: Starting task 66.0 in stage 0.0 (TID 66) (m2, executor 2, partition 66, NODE_LOCAL, 7437 bytes) ","logger":"airflow.task.hooks.airflow.providers.ssh.hooks.ssh.SSHHook","filename":"ssh.py","lineno":500}
{"timestamp":"2026-04-25T05:46:12.006270Z","level":"warning","event":"26/04/25 14:46:12 INFO TaskSetManager: Finished task 64.0 in stage 0.0 (TID 64) in 31 ms on m2 (executor 2) (65/892)","logger":"airflow.task.hooks.airflow.providers.ssh.hooks.ssh.SSHHook","filename":"ssh.py","lineno":500}
{"timestamp":"2026-04-25T05:46:12.010050Z","level":"warning","event":"26/04/25 14:46:12 INFO TaskSetManager: Starting task 67.0 in stage 0.0 (TID 67) (s1, executor 1, partition 67, NODE_LOCAL, 7437 bytes) ","logger":"airflow.task.hooks.airflow.providers.ssh.hooks.ssh.SSHHook","filename":"ssh.py","lineno":500}
{"timestamp":"2026-04-25T05:46:12.010888Z","level":"warning","event":"26/04/25 14:46:12 INFO TaskSetManager: Finished task 65.0 in stage 0.0 (TID 65) in 33 ms on s1 (executor 1) (66/892)","logger":"airflow.task.hooks.airflow.providers.ssh.hooks.ssh.SSHHook","filename":"ssh.py","lineno":500}
{"timestamp":"2026-04-25T05:46:12.029779Z","level":"warning","event":"26/04/25 14:46:12 INFO TaskSetManager: Starting task 68.0 in stage 0.0 (TID 68) (m2, executor 2, partition 68, NODE_LOCAL, 7437 bytes) ","logger":"airflow.task.hooks.airflow.providers.ssh.hooks.ssh.SSHHook","filename":"ssh.py","lineno":500}
{"timestamp":"2026-04-25T05:46:12.030375Z","level":"warning","event":"26/04/25 14:46:12 INFO TaskSetManager: Finished task 66.0 in stage 0.0 (TID 66) in 28 ms on m2 (executor 2) (67/892)","logger":"airflow.task.hooks.airflow.providers.ssh.hooks.ssh.SSHHook","filename":"ssh.py","lineno":500}
{"timestamp":"2026-04-25T05:46:12.040411Z","level":"warning","event":"26/04/25 14:46:12 INFO TaskSetManager: Starting task 69.0 in stage 0.0 (TID 69) (s1, executor 1, partition 69, NODE_LOCAL, 7437 bytes) ","logger":"airflow.task.hooks.airflow.providers.ssh.hooks.ssh.SSHHook","filename":"ssh.py","lineno":500}
{"timestamp":"2026-04-25T05:46:12.047359Z","level":"warning","event":"26/04/25 14:46:12 INFO TaskSetManager: Finished task 67.0 in stage 0.0 (TID 67) in 35 ms on s1 (executor 1) (68/892)","logger":"airflow.task.hooks.airflow.providers.ssh.hooks.ssh.SSHHook","filename":"ssh.py","lineno":500}
{"timestamp":"2026-04-25T05:46:12.065117Z","level":"warning","event":"26/04/25 14:46:12 INFO TaskSetManager: Starting task 70.0 in stage 0.0 (TID 70) (m2, executor 2, partition 70, NODE_LOCAL, 7437 bytes) ","logger":"airflow.task.hooks.airflow.providers.ssh.hooks.ssh.SSHHook","filename":"ssh.py","lineno":500}
{"timestamp":"2026-04-25T05:46:12.065876Z","level":"warning","event":"26/04/25 14:46:12 INFO TaskSetManager: Finished task 68.0 in stage 0.0 (TID 68) in 39 ms on m2 (executor 2) (69/892)","logger":"airflow.task.hooks.airflow.providers.ssh.hooks.ssh.SSHHook","filename":"ssh.py","lineno":500}
{"timestamp":"2026-04-25T05:46:12.091436Z","level":"warning","event":"26/04/25 14:46:12 INFO TaskSetManager: Starting task 71.0 in stage 0.0 (TID 71) (s1, executor 1, partition 71, NODE_LOCAL, 7437 bytes) ","logger":"airflow.task.hooks.airflow.providers.ssh.hooks.ssh.SSHHook","filename":"ssh.py","lineno":500}
{"timestamp":"2026-04-25T05:46:12.091624Z","level":"warning","event":"26/04/25 14:46:12 INFO TaskSetManager: Finished task 69.0 in stage 0.0 (TID 69) in 52 ms on s1 (executor 1) (70/892)","logger":"airflow.task.hooks.airflow.providers.ssh.hooks.ssh.SSHHook","filename":"ssh.py","lineno":500}
{"timestamp":"2026-04-25T05:46:12.096625Z","level":"warning","event":"26/04/25 14:46:12 INFO TaskSetManager: Starting task 72.0 in stage 0.0 (TID 72) (m2, executor 2, partition 72, NODE_LOCAL, 7437 bytes) ","logger":"airflow.task.hooks.airflow.providers.ssh.hooks.ssh.SSHHook","filename":"ssh.py","lineno":500}
{"timestamp":"2026-04-25T05:46:12.097120Z","level":"warning","event":"26/04/25 14:46:12 INFO TaskSetManager: Finished task 70.0 in stage 0.0 (TID 70) in 33 ms on m2 (executor 2) (71/892)","logger":"airflow.task.hooks.airflow.providers.ssh.hooks.ssh.SSHHook","filename":"ssh.py","lineno":500}
{"timestamp":"2026-04-25T05:46:12.127713Z","level":"warning","event":"26/04/25 14:46:12 INFO TaskSetManager: Starting task 73.0 in stage 0.0 (TID 73) (m2, executor 2, partition 73, NODE_LOCAL, 7437 bytes) ","logger":"airflow.task.hooks.airflow.providers.ssh.hooks.ssh.SSHHook","filename":"ssh.py","lineno":500}
{"timestamp":"2026-04-25T05:46:12.129515Z","level":"warning","event":"26/04/25 14:46:12 INFO TaskSetManager: Starting task 74.0 in stage 0.0 (TID 74) (s1, executor 1, partition 74, NODE_LOCAL, 7437 bytes) ","logger":"airflow.task.hooks.airflow.providers.ssh.hooks.ssh.SSHHook","filename":"ssh.py","lineno":500}
{"timestamp":"2026-04-25T05:46:12.131397Z","level":"warning","event":"26/04/25 14:46:12 INFO TaskSetManager: Finished task 71.0 in stage 0.0 (TID 71) in 41 ms on s1 (executor 1) (72/892)","logger":"airflow.task.hooks.airflow.providers.ssh.hooks.ssh.SSHHook","filename":"ssh.py","lineno":500}
{"timestamp":"2026-04-25T05:46:12.131952Z","level":"warning","event":"26/04/25 14:46:12 INFO TaskSetManager: Finished task 72.0 in stage 0.0 (TID 72) in 38 ms on m2 (executor 2) (73/892)","logger":"airflow.task.hooks.airflow.providers.ssh.hooks.ssh.SSHHook","filename":"ssh.py","lineno":500}
{"timestamp":"2026-04-25T05:46:12.155398Z","level":"warning","event":"26/04/25 14:46:12 INFO TaskSetManager: Starting task 75.0 in stage 0.0 (TID 75) (m2, executor 2, partition 75, NODE_LOCAL, 7437 bytes) ","logger":"airflow.task.hooks.airflow.providers.ssh.hooks.ssh.SSHHook","filename":"ssh.py","lineno":500}
{"timestamp":"2026-04-25T05:46:12.156105Z","level":"warning","event":"26/04/25 14:46:12 INFO TaskSetManager: Finished task 73.0 in stage 0.0 (TID 73) in 31 ms on m2 (executor 2) (74/892)","logger":"airflow.task.hooks.airflow.providers.ssh.hooks.ssh.SSHHook","filename":"ssh.py","lineno":500}
{"timestamp":"2026-04-25T05:46:12.160490Z","level":"warning","event":"26/04/25 14:46:12 INFO TaskSetManager: Finished task 74.0 in stage 0.0 (TID 74) in 31 ms on s1 (executor 1) (75/892)","logger":"airflow.task.hooks.airflow.providers.ssh.hooks.ssh.SSHHook","filename":"ssh.py","lineno":500}
{"timestamp":"2026-04-25T05:46:12.161751Z","level":"warning","event":"26/04/25 14:46:12 INFO TaskSetManager: Starting task 76.0 in stage 0.0 (TID 76) (s1, executor 1, partition 76, NODE_LOCAL, 7437 bytes) ","logger":"airflow.task.hooks.airflow.providers.ssh.hooks.ssh.SSHHook","filename":"ssh.py","lineno":500}
